Workbook
Name RawData: main!$A$1:$FJ$175
Name Returns: main!$FO$3:$LV$175
Name VarianceCovariance: #REF!

Sheet main
A1: Ticker | B1: MSCI World | C1: UCB.BR | D1: EBAY | E1: BHP.AX | F1: 7203.T | G1: PLTR | H1: SOF.BR | I1: 005380.KS | J1: HOOD | K1: MSFT | L1: BMW.DE | M1: YZCFF | N1: NAB.AX | O1: BKNG | P1: ISP.MI | Q1: MELI | R1: 1810.HK | S1: AAPL | T1: VOW3.DE | U1: 005930.KS | V1: 6033.KL | W1: NVDA | X1: BBVA | Y1: UNH | Z1: BABA | AA1: TSLA | AB1: BBD | AC1: SNAP | AD1: SONY | AE1: AMZN | AF1: MC.PA | AG1: KO | AH1: HFG.DE | AI1: TM | AJ1: PFE | AK1: ORSTED.CO | AL1: RACE | AM1: INTC | AN1: NTDOY | AO1: AIR.PA | AP1: JPM | AQ1: ENGI.PA | AR1: 000065.SZ | AS1: NESN.SW | AT1: FWONK | AU1: PAG | AV1: HMC | AW1: MBG.DE | AX1: NOK | AY1: HPQ | AZ1: PINS | BA1: 9984.T | BB1: ASML.AS | BC1: MVST | BD1: 603080.SS | BE1: ADBE | BF1: NFLX | BG1: SIE.DE | BH1: SHEL | BI1: CAT | BJ1: SAN.MC | BK1: 6752.T | BL1: EA | BM1: GE | BN1: GLEN.L | BO1: TCS.NS | BP1: MQBKY | BQ1: BLK | BR1: DIS | BS1: OR.PA | BT1: 1211.HK | BU1: TTE.PA | BV1: F | BW1: WMT | BX1: META | BY1: JNJ | BZ1: SHOP | CA1: PEP | CB1: BNP.PA | CC1: 000270.KS | CD1: ADS.DE | CE1: ZM | CF1: LOTB.BR | CG1: TNDM | CH1: F9D.SI | CI1: DIE.BR | CJ1: AMD | CK1: NVO | CL1: B4F.F | CM1: KAEPY | CN1: 0992.HK | CO1: QUBT | CP1: BA.L | CQ1: ABBV | CR1: ALIZF | CS1: SAP | CT1: V | CU1: TATAMOTORS.NS | CV1: ORCL | CW1: MA | CX1: CA.PA | CY1: 0700.HK | CZ1: 2318.HK | DA1: MAERSK-B.CO | DB1: JPM | DC1: MG | DD1: COLR.BR | DE1: 7269.T | DF1: SAF.PA | DG1: JNJ | DH1: IBE.MC | DI1: FUJHY | DJ1: ANZ.AX | DK1: NKE | DL1: 9601.T | DM1: CS.PA | DN1: UL | DO1: HEIA.AS | DP1: SBUX | DQ1: 006400.KS | DR1: SPOT | DS1: 0001.HK | DT1: SMCI | DU1: UPST | DV1: CRSR | DW1: BLNK | DX1: PATH | DY1: VALE | DZ1: EQNR.OL | EA1: MMM | EB1: BEP | EC1: ADYEN.AS | ED1: MT | EE1: CEVA | EF1: INFY | EG1: PAH3.DE | EH1: TDG | EI1: DHR | EJ1: 0857.HK | EK1: ULVR.L | EL1: 2222.SR | EM1: ROG.SW | EN1: PG | EO1: VOLV-B.ST | EP1: 6501.T | EQ1: TSM | ER1: AI.PA | ES1: PME.AX | ET1: 000333.SZ | EU1: SOLB.BR | EV1: BRK-B | EW1: ACGBY | EX1: BA | EY1: IBM | EZ1: BP | FA1: 0941.HK | FB1: E | FC1: XTP.WA | FD1: ELABS.OL | FE1: KHC | FF1: 1821.T | FG1: SAN.PA | FH1: COST | FI1: NHY.OL | FJ1: 9983.T | FN1: MSCI | FO1: UCB.BR | FP1: EBAY | FQ1: BHP.AX | FR1: 7203.T | FS1: PLTR | FT1: SOF.BR | FU1: 005380.KS | FV1: HOOD | FW1: MSFT | FX1: BMW.DE | FY1: YZCFF | FZ1: NAB.AX | GA1: BKNG | GB1: ISP.MI | GC1: MELI | GD1: 1810.HK | GE1: AAPL | GF1: VOW3.DE | GG1: 005930.KS | GH1: 6033.KL | GI1: NVDA | GJ1: BBVA | GK1: UNH | GL1: BABA | GM1: TSLA | GN1: BBD | GO1: SNAP | GP1: SONY | GQ1: AMZN | GR1: MC.PA | GS1: KO | GT1: HFG.DE | GU1: TM | GV1: PFE | GW1: ORSTED.CO | GX1: RACE | GY1: INTC | GZ1: NTDOY | HA1: AIR.PA | HB1: JPM | HC1: ENGI.PA | HD1: 000065.SZ | HE1: NESN.SW | HF1: FWONK | HG1: PAG | HH1: HMC | HI1: MBG.DE | HJ1: NOK | HK1: HPQ | HL1: PINS | HM1: 9984.T | HN1: ASML.AS | HO1: MVST | HP1: 603080.SS | HQ1: ADBE | HR1: NFLX | HS1: SIE.DE | HT1: SHEL | HU1: CAT | HV1: SAN.MC | HW1: 6752.T | HX1: EA | HY1: GE | HZ1: GLEN.L | IA1: TCS.NS | IB1: MQBKY | IC1: BLK | ID1: DIS | IE1: OR.PA | IF1: 1211.HK | IG1: TTE.PA | IH1: F | II1: WMT | IJ1: META | IK1: JNJ | IL1: SHOP | IM1: PEP | IN1: BNP.PA | IO1: 000270.KS | IP1: ADS.DE | IQ1: ZM | IR1: LOTB.BR | IS1: TNDM | IT1: F9D.SI | IU1: DIE.BR | IV1: AMD | IW1: NVO | IX1: B4F.F | IY1: KAEPY | IZ1: 0992.HK | JA1: QUBT | JB1: BA.L | JC1: ABBV | JD1: ALIZF | JE1: SAP | JF1: V | JG1: TATAMOTORS.NS | JH1: ORCL | JI1: MA | JJ1: CA.PA | JK1: 0700.HK | JL1: 2318.HK | JM1: MAERSK-B.CO | JN1: JPM | JO1: MG | JP1: COLR.BR | JQ1: 7269.T | JR1: SAF.PA | JS1: JNJ | JT1: IBE.MC | JU1: FUJHY | JV1: ANZ.AX | JW1: NKE | JX1: 9601.T | JY1: CS.PA | JZ1: UL | KA1: HEIA.AS | KB1: SBUX | KC1: 006400.KS | KD1: SPOT | KE1: 0001.HK | KF1: SMCI | KG1: UPST | KH1: CRSR | KI1: BLNK | KJ1: PATH | KK1: VALE | KL1: EQNR.OL | KM1: MMM | KN1: BEP | KO1: ADYEN.AS | KP1: MT | KQ1: CEVA | KR1: INFY | KS1: PAH3.DE | KT1: TDG | KU1: DHR | KV1: 0857.HK | KW1: ULVR.L | KX1: 2222.SR | KY1: ROG.SW | KZ1: PG | LA1: VOLV-B.ST | LB1: 6501.T | LC1: TSM | LD1: AI.PA | LE1: PME.AX | LF1: 000333.SZ | LG1: SOLB.BR | LH1: BRK-B | LI1: ACGBY | LJ1: BA | LK1: IBM | LL1: BP | LM1: 0941.HK | LN1: E | LO1: XTP.WA | LP1: ELABS.OL | LQ1: KHC | LR1: 1821.T | LS1: SAN.PA | LT1: COST | LU1: NHY.OL | LV1: 9983.T
A2: 44788 | B2: 2787.71 | C2: 70.78 | D2: 44.15 | E2: 33.43 | F2: 1940.41 | G2: 8.51 | H2: 201.27 | I2: 160734.12 | J2: 9.26 | K2: 278.61 | L2: 62.42 | M2: 0.07 | N2: 26.48 | O2: 2057.25 | P2: 1.38 | Q2: 909.76 | R2: 11.66 | S2: 168.85 | T2: 101.31 | U2: 56942.82 | V2: 15.05 | W2: 17.82 | X2: 3.82 | Y2: 519.33 | Z2: 85.12 | AA2: 296.67 | AB2: 2.95 | AC2: 11.56 | AD2: 17 | AE2: 138.23 | AF2: 660.02 | AG2: 59.11 | AH2: 28.14 | AI2: 143.4 | AJ2: 41.69 | AK2: 774.92 | AL2: 202.63 | AM2: 33.66 | AN2: 10.79 | AO2: 100.69 | AP2: 109.2 | AQ2: 9.88 | AR2: 8.14 | AS2: 106.54 | AT2: 66.57 | AU2: 111.29 | AV2: 24.02 | AW2: 45.93 | AX2: 4.56 | AY2: 30.4 | AZ2: 21.77 | BA2: 5644.38 | BB2: 529.61 | BC2: 2.61 | BD2: 14.74 | BE2: 425.06 | BF2: 241.16 | BG2: 99.88 | BH2: 46.88 | BI2: 185.14 | BJ2: 2.24 | BK2: 1042.35 | BL2: 128.13 | BM2: 47.64 | BN2: 486.23 | BO2: 3091.91 | BP2: 111.76 | BQ2: 657.8 | BR2: 118.17 | BS2: 345.46 | BT2: 90.29 | BU2: 43.52 | BV2: 12.52 | BW2: 43.96 | BX2: 166.93 | BY2: 153.5 | BZ2: 34.2 | CA2: 162.67 | CB2: 37.93 | CC2: 65200.08 | CD2: 162.9 | CE2: 99.5 | CF2: 5683.87 | CG2: 48.82 | CH2: 0.78 | CI2: 97.24 | CJ2: 95.95 | CK2: 50.24 | CL2: 41.9 | CM2: 4.49 | CN2: 6.34 | CO2: 3.25 | CP2: 802.4 | CQ2: 124.47 | CR2: 151.61 | CS2: 88.21 | CT2: 208.01 | CU2: 462.67 | CV2: 75.41 | CW2: 347.55 | CX2: 14.66 | CY2: 291.97 | CZ2: 35.6 | DA2: 12197.22 | DB2: 109.2 | DC2: 5.75 | DD2: 23.84 | DE2: 1134.75 | DF2: 106.56 | DG2: 153.5 | DH2: 9.57 | DI2: 8.62 | DJ2: 19.2 | DK2: 107.36 | DL2: 12776.79 | DM2: 20.42 | DN2: 42.76 | DO2: 90.03 | DP2: 80.94 | DQ2: 613219 | DR2: 111.43 | DS2: 43.48 | DT2: 6.98 | DU2: 28.46 | DV2: 15.91 | DW2: 22.79 | DX2: 18 | DY2: 10.06 | DZ2: 296.93 | EA2: 106.71 | EB2: 33.07 | EC2: 1617.8 | ED2: 22.35 | EE2: 32.24 | EF2: 18.21 | EG2: 58.05 | EH2: 536.92 | EI2: 255.24 | EJ2: 2.56 | EK2: 3999.84 | EL2: 30.08 | EM2: 289.77 | EN2: 138.79 | EO2: 147.62 | EP2: 1333.25 | EQ2: 82.77 | ER2: 117.64 | ES2: 53.53 | ET2: 46.18 | EU2: 11.45 | EV2: 297.28 | EW2: 6.47 | EX2: 162.92 | EY2: 123.23 | EZ2: 27 | FA2: 41.34 | FB2: 19.39 | FC2: 60.6 | FD2: 18.22 | FE2: 33.02 | FF2: 414.59 | FG2: 72.4 | FH2: 532.02 | FI2: 55.69 | FJ2: 27579.57
A3: 44795 | B3: 2694.62 | C3: 69.16 | D3: 41.77 | E3: 34.45 | F3: 1902.5 | G3: 7.94 | H3: 191.51 | I3: 163695.03 | J3: 9.38 | K3: 261.58 | L3: 60.21 | M3: 0.07 | N3: 26.21 | O3: 1883.79 | P3: 1.32 | Q3: 877.8 | R3: 11.78 | S3: 161.08 | T3: 97.96 | U3: 56101.3 | V3: 15.33 | W3: 16.24 | X3: 3.59 | Y3: 501.27 | Z3: 93.07 | AA3: 288.09 | AB3: 2.97 | AC3: 10.67 | AD3: 16.02 | AE3: 130.75 | AF3: 632.33 | AG3: 57.24 | AH3: 24.58 | AI3: 139.1 | AJ3: 39.71 | AK3: 760.4 | AL3: 193.58 | AM3: 31.74 | AN3: 10.31 | AO3: 96.6 | AP3: 105.55 | AQ3: 9.74 | AR3: 10.11 | AS3: 105.24 | AT3: 66.21 | AU3: 112.86 | AV3: 23.39 | AW3: 43.48 | AX3: 4.41 | AY3: 27.88 | AZ3: 23.08 | BA3: 5586.6 | BB3: 506.59 | BC3: 2.46 | BD3: 14.65 | BE3: 381.02 | BF3: 223.28 | BG3: 94.98 | BH3: 48.67 | BI3: 181.66 | BJ3: 2.13 | BK3: 1027.31 | BL3: 129.79 | BM3: 46.13 | BN3: 497.96 | BO3: 2942.56 | BP3: 108.03 | BQ3: 623.33 | BR3: 112.2 | BS3: 336.49 | BT3: 85.64 | BU3: 44.57 | BV3: 12.15 | BW3: 42.22 | BX3: 160.79 | BY3: 148.93 | BZ3: 32.42 | CA3: 158.04 | CB3: 36.49 | CC3: 66635.83 | CD3: 149.07 | CE3: 81.41 | CF3: 5654.52 | CG3: 46.68 | CH3: 0.78 | CI3: 93.09 | CJ3: 91.18 | CK3: 52.23 | CL3: 39.6 | CM3: 4.49 | CN3: 6.07 | CO3: 3.15 | CP3: 812.39 | CQ3: 120.36 | CR3: 146.7 | CS3: 81.1 | CT3: 198.31 | CU3: 456.82 | CV3: 71.56 | CW3: 325.65 | CX3: 14.23 | CY3: 300.5 | CZ3: 38.13 | DA3: 11397.1 | DB3: 105.55 | DC3: 5.57 | DD3: 23.17 | DE3: 1122.9 | DF3: 101.59 | DG3: 148.93 | DH3: 9.56 | DI3: 8.3 | DJ3: 19.08 | DK3: 102.73 | DL3: 12528.79 | DM3: 19.72 | DN3: 41.5 | DO3: 85.8 | DP3: 78.28 | DQ3: 581466.56 | DR3: 109.31 | DS3: 43.39 | DT3: 6.98 | DU3: 25.21 | DV3: 15.84 | DW3: 21.38 | DX3: 16.95 | DY3: 10.5 | DZ3: 321.64 | EA3: 95.88 | EB3: 31.99 | EC3: 1602 | ED3: 22.24 | EE3: 30.47 | EF3: 17.16 | EG3: 57.55 | EH3: 539.39 | EI3: 244.67 | EJ3: 2.81 | EK3: 3930.91 | EL3: 29.7 | EM3: 283.86 | EN3: 131.9 | EO3: 141.54 | EP3: 1337.79 | EQ3: 80.44 | ER3: 111.72 | ES3: 53.06 | ET3: 45.71 | EU3: 11.03 | EV3: 289.96 | EW3: 6.56 | EX3: 164.53 | EY3: 116.12 | EZ3: 27.7 | FA3: 41.34 | FB3: 19.96 | FC3: 62.4 | FD3: 18.02 | FE3: 32.66 | FF3: 420.01 | FG3: 72.6 | FH3: 510.23 | FI3: 58.98 | FJ3: 27379.7 | FN3: =(B3-B2)/B2 -> -0.033393 | FO3: =(C3-C2)/C2 -> -0.022887821 | FP3: =(D3-D2)/D2 -> -0.053907135 | FQ3: =(E3-E2)/E2 -> 0.030511517 | FR3: =(F3-F2)/F2 -> -0.019537108 | FS3: =(G3-G2)/G2 -> -0.066980024 | FT3: =(H3-H2)/H2 -> -0.048492075 | FU3: =(I3-I2)/I2 -> 0.018421167 | ... LV3: =(FJ3-FJ2)/FJ2 -> -0.007247031
A4: 44802 | B4: 2605.21 | C4: 67.67 | D4: 41.37 | E4: 29.56 | F4: 1849.25 | G4: 7.4 | H4: 191.23 | I4: 166232.91 | J4: 9.45 | K4: 249.84 | L4: 61.85 | M4: 0.07 | N4: 26.15 | O4: 1811.78 | P4: 1.36 | Q4: 855.91 | R4: 11.16 | S4: 153.39 | T4: 103.53 | U4: 53763.74 | V4: 15.1 | W4: 13.63 | X4: 3.6 | Y4: 489.05 | Z4: 87.18 | AA4: 270.21 | AB4: 2.89 | AC4: 11.22 | AD4: 15.14 | AE4: 127.51 | AF4: 609.26 | AG4: 55.47 | AH4: 24.29 | AI4: 133.41 | AJ4: 38.76 | AK4: 717.23 | AL4: 187.11 | AM4: 29.7 | AN4: 9.93 | AO4: 93.79 | AP4: 104.67 | AQ4: 9.29 | AR4: 10.26 | AS4: 103.35 | AT4: 61.68 | AU4: 106.65 | AV4: 23.24 | AW4: 45.52 | AX4: 4.46 | AY4: 24.55 | AZ4: 22.07 | BA4: 5379 | BB4: 470.4 | BC4: 2.36 | BD4: 14.79 | BE4: 368.14 | BF4: 226.11 | BG4: 96.81 | BH4: 47.21 | BI4: 171.16 | BJ4: 2.15 | BK4: 1021.84 | BL4: 123.07 | BM4: 44.39 | BN4: 452.4 | BO4: 2858.72 | BP4: 107.44 | BQ4: 606.39 | BR4: 109.38 | BS4: 328.91 | BT4: 73.81 | BU4: 42.59 | BV4: 11.95 | BW4: 42.67 | BX4: 159.34 | BY4: 148.54 | BZ4: 30.11 | CA4: 154.08 | CB4: 37.79 | CC4: 68240.5 | CD4: 145.87 | CE4: 80.79 | CF4: 5527.35 | CG4: 44.75 | CH4: 0.78 | CI4: 90.87 | CJ4: 80.24 | CK4: 49.13 | CL4: 35.78 | CM4: 4.49 | CN4: 5.5 | CO4: 2.96 | CP4: 763.83 | CQ4: 120.87 | CR4: 151.53 | CS4: 80.17 | CT4: 193.29 | CU4: 453.58 | CV4: 71.59 | CW4: 316.43 | CX4: 13.94 | CY4: 304.58 | CZ4: 37.35 | DA4: 10640.39 | DB4: 104.67 | DC4: 5.41 | DD4: 23.09 | DE4: 1149.86 | DF4: 99.23 | DG4: 148.54 | DH4: 9.24 | DI4: 8.47 | DJ4: 18.91 | DK4: 100.32 | DL4: 11913.76 | DM4: 20.1 | DN4: 40.22 | DO4: 83.73 | DP4: 77.24 | DQ4: 571543.88 | DR4: 104.42 | DS4: 41.6 | DT4: 6.45 | DU4: 24.38 | DV4: 14.07 | DW4: 19.55 | DX4: 16.1 | DY4: 9.5 | DZ4: 300.77 | EA4: 90.32 | EB4: 31.63 | EC4: 1520.6 | ED4: 21.48 | EE4: 27.67 | EF4: 16.65 | EG4: 62.36 | EH4: 513.9 | EI4: 235.15 | EJ4: 2.74 | EK4: 3901.94 | EL4: 29.13 | EM4: 285.6 | EN4: 127.14 | EO4: 140.08 | EP4: 1308.23 | EQ4: 76.79 | ER4: 107.66 | ES4: 53 | ET4: 45.38 | EU4: 11.3 | EV4: 277.67 | EW4: 6.42 | EX4: 151.82 | EY4: 113.81 | EZ4: 26.67 | FA4: 40.75 | FB4: 19.42 | FC4: 59 | FD4: 18.02 | FE4: 32.31 | FF4: 406.46 | FG4: 72.2 | FH4: 498.03 | FI4: 54.38 | FJ4: 26212.68 | FN4: =(B4-B3)/B3 -> -0.033180931 | FO4: =(C4-C3)/C3 -> -0.021544245 | FP4: =(D4-D3)/D3 -> -0.0095762509 | FQ4: =(E4-E3)/E3 -> -0.14194485 | FR4: =(F4-F3)/F3 -> -0.027989488 | FS4: =(G4-G3)/G3 -> -0.068010076 | FT4: =(H4-H3)/H3 -> -0.0014620646 | FU4: =(I4-I3)/I3 -> 0.015503708 | ... LV4: =(FJ4-FJ3)/FJ3 -> -0.04262355
A5: 44809 | B5: 2682.9 | C5: 68.58 | D5: 42.51 | E5: 32.71 | F5: 1875.88 | G5: 7.79 | H5: 193.43 | I5: 169193.81 | J5: 10.6 | K5: 258.04 | L5: 60.53 | M5: 0.07 | N5: 25.56 | O5: 1952.87 | P5: 1.43 | Q5: 970.99 | R5: 10.8 | S5: 154.92 | T5: 102.16 | U5: 51987.21 | V5: 14.96 | W5: 14.37 | X5: 3.95 | Y5: 496.62 | Z5: 87.5 | AA5: 299.68 | AB5: 2.94 | AC5: 12.65 | AD5: 14.78 | AE5: 133.27 | AF5: 616.54 | AG5: 56.53 | AH5: 26.44 | AI5: 133.43 | AJ5: 40.58 | AK5: 718.51 | AL5: 191.63 | AM5: 29.93 | AN5: 10.09 | AO5: 90.99 | AP5: 109.7 | AQ5: 9.76 | AR5: 10.21 | AS5: 101.71 | AT5: 63.3 | AU5: 103.09 | AV5: 23.04 | AW5: 44.57 | AX5: 4.59 | AY5: 25.1 | AZ5: 25.55 | BA5: 5385.85 | BB5: 483.76 | BC5: 2.53 | BD5: 14.22 | BE5: 394.78 | BF5: 233.57 | BG5: 96.92 | BH5: 47.58 | BI5: 179.36 | BJ5: 2.24 | BK5: 1027.77 | BL5: 126.8 | BM5: 45.38 | BN5: 487.7 | BO5: 2938.4 | BP5: 110.39 | BQ5: 640.85 | BR5: 113.29 | BS5: 329.38 | BT5: 71.61 | BU5: 41.16 | BV5: 12.16 | BW5: 43.9 | BX5: 168.11 | BY5: 151.25 | BZ5: 34.81 | CA5: 157.44 | CB5: 38.74 | CC5: 68324.95 | CD5: 142.99 | CE5: 82.62 | CF5: 5370.82 | CG5: 55.98 | CH5: 0.77 | CI5: 93.57 | CJ5: 85.45 | CK5: 52.15 | CL5: 34.26 | CM5: 4.49 | CN5: 5.38 | CO5: 2.96 | CP5: 783.81 | CQ5: 126.16 | CR5: 141.76 | CS5: 83.83 | CT5: 200.56 | CU5: 438.01 | CV5: 72.77 | CW5: 329.47 | CX5: 13.91 | CY5: 284.56 | CZ5: 38.82 | DA5: 10066.66 | DB5: 109.7 | DC5: 5.07 | DD5: 25.36 | DE5: 1157.76 | DF5: 100.62 | DG5: 151.25 | DH5: 9.37 | DI5: 8.82 | DJ5: 19.13 | DK5: 105.58 | DL5: 11834.4 | DM5: 20.94 | DN5: 41.49 | DO5: 85.72 | DP5: 82.59 | DQ5: 566582.56 | DR5: 110.28 | DS5: 39.78 | DT5: 6.69 | DU5: 27.53 | DV5: 14.88 | DW5: 21.83 | DX5: 14.64 | DY5: 10.55 | DZ5: 282.08 | EA5: 91.39 | EB5: 32.51 | EC5: 1487.6 | ED5: 22.31 | EE5: 28.9 | EF5: 17.55 | EG5: 57.26 | EH5: 529.9 | EI5: 253.48 | EJ5: 2.61 | EK5: 3948.89 | EL5: 28.7 | EM5: 290.58 | EN5: 129.74 | EO5: 139.77 | EP5: 1319.98 | EQ5: 77.39 | ER5: 105.86 | ES5: 54.21 | ET5: 46.61 | EU5: 11.33 | EV5: 285.77 | EW5: 6.37 | EX5: 157.52 | EY5: 115.06 | EZ5: 27.15 | FA5: 40.32 | FB5: 19.24 | FC5: 57.4 | FD5: 17.9 | FE5: 31.57 | FF5: 405.56 | FG5: 71.99 | FH5: 514.79 | FI5: 55.92 | FJ5: 26958.8 | FN5: =(B5-B4)/B4 -> 0.029821013 | FO5: =(C5-C4)/C4 -> 0.013447613 | FP5: =(D5-D4)/D4 -> 0.0275562 | FQ5: =(E5-E4)/E4 -> 0.10656292 | FR5: =(F5-F4)/F4 -> 0.014400433 | FS5: =(G5-G4)/G4 -> 0.052702703 | FT5: =(H5-H4)/H4 -> 0.011504471 | FU5: =(I5-I4)/I4 -> 0.017811756 | ... LV5: =(FJ5-FJ4)/FJ4 -> 0.028464087
A6: 44816 | B6: 2569.29 | C6: 66.44 | D6: 39.59 | E6: 32.66 | F6: 1832.56 | G6: 7.78 | H6: 174.29 | I6: 170039.78 | J6: 10.25 | K6: 238.8 | L6: 61.25 | M6: 0.07 | N6: 25.65 | O6: 1849.77 | P6: 1.49 | Q6: 919.11 | R6: 10.24 | S6: 148.36 | T6: 101.1 | U6: 52548.22 | V6: 14.43 | W6: 13.18 | X6: 4.03 | Y6: 495.02 | Z6: 82.08 | AA6: 303.35 | AB6: 2.81 | AC6: 11.3 | AD6: 14.09 | AE6: 123.53 | AF6: 604.44 | AG6: 54.01 | AH6: 25.23 | AI6: 128.99 | AJ6: 39.04 | AK6: 699.75 | AL6: 192.71 | AM6: 27.82 | AN6: 10.53 | AO6: 86.95 | AP6: 107.77 | AQ6: 9.81 | AR6: 10.4 | AS6: 97.34 | AT6: 60.68 | AU6: 97.36 | AV6: 21.82 | AW6: 45.08 | AX6: 4.19 | AY6: 24.18 | AZ6: 24.92 | BA6: 5344.73 | BB6: 451.79 | BC6: 2.24 | BD6: 15.52 | BE6: 299.5 | BF6: 240.13 | BG6: 92.44 | BH6: 46.6 | BI6: 169.87 | BJ6: 2.34 | BK6: 1025.49 | BL6: 119.72 | BM6: 40.69 | BN6: 488.59 | BO6: 2747.59 | BP6: 103.53 | BQ6: 581.84 | BR6: 106.47 | BS6: 323.42 | BT6: 69.54 | BU6: 41.11 | BV6: 11.6 | BW6: 42.73 | BX6: 145.39 | BY6: 152.97 | BZ6: 31.73 | CA6: 151.76 | CB6: 39.25 | CC6: 68493.86 | CD6: 132.94 | CE6: 78.68 | CF6: 5439.3 | CG6: 57.26 | CH6: 0.76 | CI6: 90.39 | CJ6: 76.51 | CK6: 48.74 | CL6: 35.16 | CM6: 4.49 | CN6: 5.35 | CO6: 2.75 | CP6: 764.23 | CQ6: 126.53 | CR6: 147.26 | CS6: 80.81 | CT6: 188.93 | CU6: 424.85 | CV6: 65.98 | CW6: 309.14 | CX6: 13.81 | CY6: 271.77 | CZ6: 37.39 | DA6: 9077.36 | DB6: 107.77 | DC6: 4.77 | DD6: 25.68 | DE6: 1152.65 | DF6: 95.52 | DG6: 152.97 | DH6: 9.25 | DI6: 8.41 | DJ6: 19.57 | DK6: 99.06 | DL6: 11913.76 | DM6: 21.21 | DN6: 40.74 | DO6: 84.26 | DP6: 85.03 | DQ6: 597342.75 | DR6: 100.34 | DS6: 41.39 | DT6: 6.23 | DU6: 24.47 | DV6: 13.87 | DW6: 22.05 | DX6: 14.03 | DY6: 10.13 | DZ6: 282.83 | EA6: 86.58 | EB6: 33.01 | EC6: 1319.6 | ED6: 21.08 | EE6: 27.56 | EF6: 16 | EG6: 57.27 | EH6: 497.42 | EI6: 241.82 | EJ6: 2.73 | EK6: 3939.9 | EL6: 28.05 | EM6: 292.41 | EN6: 128.18 | EO6: 137.01 | EP6: 1274.13 | EQ6: 73.93 | ER6: 104.97 | ES6: 53.44 | ET6: 48.16 | EU6: 11 | EV6: 274.81 | EW6: 6.3 | EX6: 144.29 | EY6: 113.35 | EZ6: 26.57 | FA6: 42.27 | FB6: 18.67 | FC6: 55.8 | FD6: 17.52 | FE6: 30.05 | FF6: 408.27 | FG6: 72.57 | FH6: 483.67 | FI6: 53.67 | FJ6: 26340.51 | FN6: =(B6-B5)/B5 -> -0.042345969 | FO6: =(C6-C5)/C5 -> -0.031204433 | FP6: =(D6-D5)/D5 -> -0.06868972 | FQ6: =(E6-E5)/E5 -> -0.0015285845 | FR6: =(F6-F5)/F5 -> -0.023093162 | FS6: =(G6-G5)/G5 -> -0.001283697 | FT6: =(H6-H5)/H5 -> -0.098950525 | FU6: =(I6-I5)/I5 -> 0.0050000056 | ... LV6: =(FJ6-FJ5)/FJ5 -> -0.022934626
A7: 44823 | B7: 2438.5 | C7: 66.98 | D7: 36 | E7: 32.78 | F7: 1830.3 | G7: 7.4 | H7: 169.8 | I7: 161157.08 | J7: 9.44 | K7: 232.15 | L7: 58.78 | M7: 0.07 | N7: 25.13 | O7: 1646.14 | P7: 1.38 | Q7: 815.01 | R7: 9.46 | S7: 148.09 | T7: 97.42 | U7: 50958.68 | V7: 14.5 | W7: 12.5 | X7: 3.75 | Y7: 487.98 | Z7: 74.84 | AA7: 275.33 | AB7: 3 | AC7: 10.32 | AD7: 13.42 | AE7: 113.78 | AF7: 570.13 | AG7: 53.54 | AH7: 22 | AI7: 125.82 | AJ7: 37.39 | AK7: 664.98 | AL7: 182.29 | AM7: 26.18 | AN7: 10.39 | AO7: 87.18 | AP7: 100.46 | AQ7: 9.54 | AR7: 9.57 | AS7: 97.57 | AT7: 55.99 | AU7: 93.39 | AV7: 20.88 | AW7: 42.62 | AX7: 3.86 | AY7: 22.71 | AZ7: 22.59 | BA7: 5232.11 | BB7: 429.59 | BC7: 1.9 | BD7: 14.48 | BE7: 284.56 | BF7: 226.41 | BG7: 91.04 | BH7: 42.67 | BI7: 155.46 | BJ7: 2.23 | BK7: 998.14 | BL7: 113.73 | BM7: 39.56 | BN7: 460.88 | BO7: 2723.25 | BP7: 95.48 | BQ7: 549.03 | BR7: 97.87 | BS7: 310.78 | BT7: 68.06 | BU7: 38.42 | BV7: 9.7 | BW7: 41.72 | BX7: 139.55 | BY7: 152.17 | BZ7: 28.76 | CA7: 153.17 | CB7: 37.33 | CC7: 65537.9 | CD7: 128.83 | CE7: 74.45 | CF7: 5018.63 | CG7: 47.42 | CH7: 0.74 | CI7: 83.6 | CJ7: 67.96 | CK7: 47.06 | CL7: 33.68 | CM7: 4.49 | CN7: 5.18 | CO7: 2.27 | CP7: 795.2 | CQ7: 125.24 | CR7: 142.8 | CS7: 76.51 | CT7: 179.8 | CU7: 415.62 | CV7: 61.88 | CW7: 288 | CX7: 12.47 | CY7: 254.9 | CZ7: 34.33 | DA7: 8581.16 | DB7: 100.46 | DC7: 4.82 | DD7: 24.47 | DE7: 1128.94 | DF7: 89.72 | DG7: 152.17 | DH7: 8.92 | DI7: 8.16 | DJ7: 19.43 | DK7: 92.31 | DL7: 11675.69 | DM7: 20.22 | DN7: 39.54 | DO7: 83.13 | DP7: 78.38 | DQ7: 605280.88 | DR7: 89.34 | DS7: 39.86 | DT7: 5.34 | DU7: 21.5 | DV7: 11.93 | DW7: 18.01 | DX7: 12.87 | DY7: 10.18 | DZ7: 267.83 | EA7: 83.89 | EB7: 29.71 | EC7: 1265.4 | ED7: 19.4 | EE7: 26.54 | EF7: 15.29 | EG7: 60.15 | EH7: 462.02 | EI7: 231.53 | EJ7: 2.74 | EK7: 4022.31 | EL7: 27.12 | EM7: 277.18 | EN7: 125.68 | EO7: 131.01 | EP7: 1244.38 | EQ7: 70.51 | ER7: 101.8 | ES7: 51.8 | ET7: 47.89 | EU7: 10.93 | EV7: 267.77 | EW7: 6.18 | EX7: 131.26 | EY7: 109.29 | EZ7: 24.06 | FA7: 42.51 | FB7: 17 | FC7: 57.8 | FD7: 17.24 | FE7: 29.37 | FF7: 403.75 | FG7: 69.87 | FH7: 447.46 | FI7: 46.8 | FJ7: 26311.38 | FN7: =(B7-B6)/B6 -> -0.050905114 | FO7: =(C7-C6)/C6 -> 0.008127634 | FP7: =(D7-D6)/D6 -> -0.090679465 | FQ7: =(E7-E6)/E6 -> 0.0036742192 | FR7: =(F7-F6)/F6 -> -0.0012332475 | FS7: =(G7-G6)/G6 -> -0.048843188 | FT7: =(H7-H6)/H6 -> -0.025761662 | FU7: =(I7-I6)/I6 -> -0.052238953 | ... LV7: =(FJ7-FJ6)/FJ6 -> -0.0011059011
A8: 44830 | B8: 2378.65 | C8: 68.6 | D8: 34.7 | E8: 33.08 | F8: 1693.12 | G8: 8.13 | H8: 169.8 | I8: 149313.55 | J8: 10.1 | K8: 227.25 | L8: 57.63 | M8: 0.06 | N8: 24.67 | O8: 1619.85 | P8: 1.33 | Q8: 827.78 | R8: 8.96 | S8: 136.05 | T8: 87.85 | U8: 49649.65 | V8: 14.57 | W8: 12.12 | X8: 3.64 | Y8: 479.84 | Z8: 75.97 | AA8: 265.25 | AB8: 2.89 | AC8: 9.82 | AD8: 12.56 | AE8: 113 | AF8: 576.94 | AG8: 51.18 | AH8: 21.75 | AI8: 119.41 | AJ8: 37.12 | AK8: 600.08 | AL8: 181.06 | AM8: 24.52 | AN8: 10.07 | AO8: 84.25 | AP8: 96.19 | AQ8: 9.04 | AR8: 9.22 | AS8: 97.57 | AT8: 56.56 | AU8: 91.58 | AV8: 19.17 | AW8: 41.39 | AX8: 3.87 | AY8: 22.33 | AZ8: 23.3 | BA8: 4798.31 | BB8: 421.28 | BC8: 1.81 | BD8: 15.06 | BE8: 275.2 | BF8: 235.44 | BG8: 93.41 | BH8: 44.13 | BI8: 155.3 | BJ8: 2.12 | BK8: 924.76 | BL8: 113.79 | BM8: 37.95 | BN8: 477.46 | BO8: 2743.8 | BP8: 89.82 | BQ8: 510.86 | BR8: 92.78 | BS8: 315.03 | BT8: 62.82 | BU8: 40.45 | BV8: 8.83 | BW8: 41.61 | BX8: 134.85 | BY8: 149.1 | BZ8: 26.94 | CA8: 148.39 | CB8: 34.7 | CC8: 60723.9 | CD8: 116.94 | CE8: 73.59 | CF8: 5136.03 | CG8: 47.85 | CH8: 0.66 | CI8: 87.32 | CJ8: 63.36 | CK8: 47.88 | CL8: 30.74 | CM8: 4.05 | CN8: 4.82 | CO8: 2.51 | CP8: 789.21 | CQ8: 122.68 | CR8: 137.94 | CS8: 78.22 | CT8: 173.64 | CU8: 397.44 | CV8: 58.54 | CW8: 278.94 | CX8: 11.97 | CY8: 246.93 | CZ8: 32.81 | DA8: 8599.77 | DB8: 96.19 | DC8: 4.46 | DD8: 19.01 | DE8: 1041.55 | DF8: 91.13 | DG8: 149.1 | DH8: 8.39 | DI8: 7.24 | DJ8: 18.95 | DK8: 79.08 | DL8: 11804.64 | DM8: 18.91 | DN8: 39.54 | DO8: 84.2 | DP8: 78.47 | DQ8: 541776 | DR8: 86.3 | DS8: 36.69 | DT8: 5.51 | DU8: 20.79 | DV8: 11.35 | DW8: 17.72 | DX8: 12.61 | DY8: 10.4 | DZ8: 283.59 | EA8: 82.04 | EB8: 26.94 | EC8: 1301.8 | ED8: 19 | EE8: 26.23 | EF8: 15.62 | EG8: 49.82 | EH8: 448.61 | EI8: 225.44 | EJ8: 2.57 | EK8: 3964.87 | EL8: 27.66 | EM8: 289.86 | EN8: 117.03 | EO8: 130.62 | EP8: 1158.54 | EQ8: 65.45 | ER8: 101.31 | ES8: 49.71 | ET8: 44.6 | EU8: 10.93 | EV8: 267.02 | EW8: 6.02 | EX8: 121.08 | EY8: 105.81 | EZ8: 24.46 | FA8: 40.95 | FB8: 17.58 | FC8: 58 | FD8: 16.78 | FE8: 28.88 | FF8: 401.95 | FG8: 69.51 | FH8: 453.1 | FI8: 50 | FJ8: 24832.01 | FN8: =(B8-B7)/B7 -> -0.024543777 | FO8: =(C8-C7)/C7 -> 0.024186324 | FP8: =(D8-D7)/D7 -> -0.036111111 | FQ8: =(E8-E7)/E7 -> 0.0091519219 | FR8: =(F8-F7)/F7 -> -0.074949462 | FS8: =(G8-G7)/G7 -> 0.098648649 | FT8: =(H8-H7)/H7 -> 0 | FU8: =(I8-I7)/I7 -> -0.073490597 | ... LV8: =(FJ8-FJ7)/FJ7 -> -0.056225481
A9: 44837 | B9: 2417.72 | C9: 70.16 | D9: 35.4 | E9: 34.4 | F9: 1815.17 | G9: 8.15 | H9: 173.72 | I9: 148467.58 | J9: 10.8 | K9: 228.55 | L9: 59.04 | M9: 0.06 | N9: 25.81 | O9: 1661.2 | P9: 1.33 | Q9: 881.99 | R9: 9.08 | S9: 137.91 | T9: 90.55 | U9: 52909.28 | V9: 14.54 | W9: 12.06 | X9: 3.69 | Y9: 479.66 | Z9: 77.15 | AA9: 223.07 | AB9: 3.1 | AC9: 10.66 | AD9: 13.07 | AE9: 114.56 | AF9: 584.31 | AG9: 49.8 | AH9: 20.62 | AI9: 126.13 | AJ9: 35.9 | AK9: 584.87 | AL9: 181.06 | AM9: 24.47 | AN9: 10.14 | AO9: 87.51 | AP9: 97.56 | AQ9: 9.13 | AR9: 8.57 | AS9: 96.61 | AT9: 60.72 | AU9: 92.94 | AV9: 20.2 | AW9: 41.59 | AX9: 4 | AY9: 22.44 | AZ9: 25.12 | BA9: 5413.89 | BB9: 434.54 | BC9: 1.86 | BD9: 13.44 | BE9: 288.77 | BF9: 224.75 | BG9: 94.76 | BH9: 46.09 | BI9: 168.05 | BJ9: 2.23 | BK9: 973.03 | BL9: 120.28 | BM9: 39.62 | BN9: 493.14 | BO9: 2798.91 | BP9: 90.36 | BQ9: 510.97 | BR9: 95.57 | BS9: 313.02 | BT9: 63.82 | BU9: 44.07 | BV9: 9.62 | BW9: 41.24 | BX9: 132.63 | BY9: 146.22 | BZ9: 27.21 | CA9: 146.89 | CB9: 34.71 | CC9: 59963.8 | CD9: 113.68 | CE9: 76.59 | CF9: 5057.77 | CG9: 52.13 | CH9: 0.68 | CI9: 90.39 | CJ9: 58.44 | CK9: 50.01 | CL9: 30.24 | CM9: 4.05 | CN9: 4.86 | CO9: 2.31 | CP9: 845.57 | CQ9: 122.67 | CR9: 143.46 | CS9: 81.38 | CT9: 179.68 | CU9: 404.86 | CV9: 60.67 | CW9: 289.36 | CX9: 12.13 | CY9: 250.82 | CZ9: 33.61 | DA9: 8714.51 | DB9: 97.56 | DC9: 4.79 | DD9: 19.43 | DE9: 1133.74 | DF9: 96.54 | DG9: 146.22 | DH9: 8.37 | DI9: 7.36 | DJ9: 20.19 | DK9: 82.93 | DL9: 11626.09 | DM9: 19.46 | DN9: 39.09 | DO9: 83.81 | DP9: 81.05 | DQ9: 586427.88 | DR9: 88.01 | DS9: 37.75 | DT9: 5.89 | DU9: 20.88 | DV9: 12.17 | DW9: 15.51 | DX9: 12.96 | DY9: 11.26 | DZ9: 301.72 | EA9: 79.83 | EB9: 26.18 | EC9: 1319.4 | ED9: 19.62 | EE9: 26.79 | EF9: 15.71 | EG9: 51.5 | EH9: 456.01 | EI9: 234.55 | EJ9: 2.69 | EK9: 3923.42 | EL9: 27.85 | EM9: 290.8 | EN9: 115.19 | EO9: 134.56 | EP9: 1253.04 | EQ9: 66.58 | ER9: 101.35 | ES9: 52.78 | ET9: 42.84 | EU9: 11.54 | EV9: 269.04 | EW9: 6.08 | EX9: 129.79 | EY9: 105.82 | EZ9: 26.63 | FA9: 41.37 | FB9: 19.06 | FC9: 57 | FD9: 16.9 | FE9: 28.6 | FF9: 401.04 | FG9: 71.07 | FH9: 449.14 | FI9: 51.34 | FJ9: 25861.42 | FN9: =(B9-B8)/B8 -> 0.016425283 | FO9: =(C9-C8)/C8 -> 0.022740525 | FP9: =(D9-D8)/D8 -> 0.020172911 | FQ9: =(E9-E8)/E8 -> 0.039903265 | FR9: =(F9-F8)/F8 -> 0.072085853 | FS9: =(G9-G8)/G8 -> 0.0024600246 | FT9: =(H9-H8)/H8 -> 0.023085984 | FU9: =(I9-I8)/I8 -> -0.0056657283 | ... LV9: =(FJ9-FJ8)/FJ8 -> 0.041454961
A10: 44844 | B10: 2376.64 | C10: 72.01 | D10: 34.95 | E10: 34.36 | F10: 1835.74 | G10: 7.53 | H10: 173.05 | I10: 141276.81 | J10: 9.89 | K10: 223.01 | L10: 61.77 | M10: 0.06 | N10: 26.61 | O10: 1646.74 | P10: 1.34 | Q10: 756.88 | R10: 8.62 | S10: 136.23 | T10: 86.38 | U10: 53003.43 | V10: 14.46 | W10: 11.21 | X10: 3.84 | Y10: 487.53 | Z10: 69.35 | AA10: 204.99 | AB10: 2.92 | AC10: 9.99 | AD10: 12.64 | AE10: 106.9 | AF10: 590.93 | AG10: 50.23 | AH10: 21.86 | AI10: 124.51 | AJ10: 36.35 | AK10: 584.57 | AL10: 176.79 | AM10: 24.65 | AN10: 10.11 | AO10: 91.55 | AP10: 103.27 | AQ10: 9.12 | AR10: 8.57 | AS10: 96.28 | AT10: 56.44 | AU10: 93.46 | AV10: 19.94 | AW10: 42.58 | AX10: 4.03 | AY10: 22.79 | AZ10: 21.35 | BA10: 5557.5 | BB10: 386.16 | BC10: 1.57 | BD10: 13.44 | BE10: 287.94 | BF10: 230 | BG10: 96.15 | BH10: 44.82 | BI10: 168.66 | BJ10: 2.24 | BK10: 970.26 | BL10: 118.38 | BM10: 41.47 | BN10: 483.65 | BO10: 2830.19 | BP10: 87.58 | BQ10: 511.48 | BR10: 92.9 | BS10: 311.31 | BT10: 62.98 | BU10: 43.73 | BV10: 9.2 | BW10: 41.84 | BX10: 125.98 | BY10: 150.11 | BZ10: 26.06 | CA10: 154.69 | CB10: 35.06 | CC10: 58274.68 | CD10: 112.26 | CE10: 72.29 | CF10: 5155.6 | CG10: 51.18 | CH10: 0.65 | CI10: 90.45 | CJ10: 55.94 | CK10: 49.88 | CL10: 29.92 | CM10: 3.62 | CN10: 4.88 | CO10: 2.03 | CP10: 790.21 | CQ10: 128.08 | CR10: 140.34 | CS10: 81.46 | CT10: 178.49 | CU10: 389.24 | CV10: 61.65 | CW10: 283.66 | CX10: 12.5 | CY10: 230.98 | CZ10: 31.94 | DA10: 9399.89 | DB10: 103.27 | DC10: 4.41 | DD10: 20.12 | DE10: 1109.54 | DF10: 99.11 | DG10: 150.11 | DH10: 8.2 | DI10: 7.2 | DJ10: 21.08 | DK10: 83.3 | DL10: 11685.61 | DM10: 19.96 | DN10: 39 | DO10: 85.16 | DP10: 80.43 | DQ10: 598335 | DR10: 81.79 | DS10: 35.93 | DT10: 5.4 | DU10: 22.94 | DV10: 11.45 | DW10: 14.36 | DX10: 11.12 | DY10: 10.2 | DZ10: 288.38 | EA10: 84.36 | EB10: 24.02 | EC10: 1283.8 | ED10: 19.89 | EE10: 24.16 | EF10: 16.4 | EG10: 48.81 | EH10: 439.6 | EI10: 221.65 | EJ10: 2.63 | EK10: 3877.96 | EL10: 27.08 | EM10: 292.5 | EN10: 115.94 | EO10: 138.15 | EP10: 1243.08 | EQ10: 61.02 | ER10: 102.24 | ES10: 51.04 | ET10: 42.84 | EU10: 11.73 | EV10: 272.67 | EW10: 5.82 | EX10: 133.15 | EY10: 106.91 | EZ10: 25.99 | FA10: 41.08 | FB10: 18.87 | FC10: 60.4 | FD10: 16.26 | FE10: 30.94 | FF10: 393.82 | FG10: 72.32 | FH10: 436.19 | FI10: 52.23 | FJ10: 27609.47 | FN10: =(B10-B9)/B9 -> -0.016991215 | FO10: =(C10-C9)/C9 -> 0.026368301 | FP10: =(D10-D9)/D9 -> -0.012711864 | FQ10: =(E10-E9)/E9 -> -0.0011627907 | FR10: =(F10-F9)/F9 -> 0.011332272 | FS10: =(G10-G9)/G9 -> -0.07607362 | FT10: =(H10-H9)/H9 -> -0.003856781 | FU10: =(I10-I9)/I9 -> -0.048433267 | ... LV10: =(FJ10-FJ9)/FJ9 -> 0.067592963
A11: 44851 | B11: 2462.42 | C11: 70.8 | D11: 36.21 | E11: 32.69 | F11: 1817 | G11: 8.29 | H11: 178.02 | I11: 141276.81 | J11: 10.14 | K11: 236.24 | L11: 63.76 | M11: 0.06 | N11: 26.89 | O11: 1796.88 | P11: 1.43 | Q11: 844.9 | R11: 9.25 | S11: 144.98 | T11: 90.1 | U11: 52626.85 | V11: 15.19 | W11: 12.45 | X11: 4.17 | Y11: 507.1 | Z11: 68.55 | AA11: 214.44 | AB11: 3.14 | AC11: 7.76 | AD11: 12.8 | AE11: 119.32 | AF11: 596.88 | AG11: 51.13 | AH11: 20.85 | AI11: 124.19 | AJ11: 38.13 | AK11: 567.58 | AL11: 184.36 | AM11: 25.66 | AN11: 10.05 | AO11: 95.65 | AP11: 113.52 | AQ11: 9.33 | AR11: 8.67 | AS11: 95.99 | AT11: 57.05 | AU11: 90.67 | AV11: 19.92 | AW11: 45.01 | AX11: 3.85 | AY11: 24 | AZ11: 21.5 | BA11: 5663.73 | BB11: 446.49 | BC11: 2.5 | BD11: 14.16 | BE11: 306.37 | BF11: 289.57 | BG11: 98.62 | BH11: 47 | BI11: 180.05 | BJ11: 2.35 | BK11: 962.86 | BL11: 122.92 | BM11: 44.69 | BN11: 501.38 | BO11: 2865.12 | BP11: 91.15 | BQ11: 554.48 | BR11: 100.37 | BS11: 295.81 | BT11: 63.15 | BU11: 44.38 | BV11: 9.61 | BW11: 43.89 | BX11: 129.21 | BY11: 153.99 | BZ11: 29.75 | CA11: 157.3 | CB11: 36.91 | CC11: 57345.66 | CD11: 102.17 | CE11: 80.98 | CF11: 5087.11 | CG11: 54.23 | CH11: 0.64 | CI11: 93.27 | CJ11: 58.82 | CK11: 50.08 | CL11: 28.98 | CM11: 3.62 | CN11: 5.09 | CO11: 2.06 | CP11: 812.39 | CQ11: 135.19 | CR11: 141.8 | CS11: 87.5 | CT11: 186.07 | CU11: 391.01 | CV11: 70.05 | CW11: 297.1 | CX11: 12.81 | CY11: 215.78 | CZ11: 30.81 | DA11: 9765.84 | DB11: 113.52 | DC11: 4.88 | DD11: 20.75 | DE11: 1084.16 | DF11: 104.83 | DG11: 153.99 | DH11: 8.34 | DI11: 7.3 | DJ11: 21.24 | DK11: 84.2 | DL11: 11695.52 | DM11: 20.39 | DN11: 40.18 | DO11: 80.21 | DP11: 82.52 | DQ11: 622149.38 | DR11: 88.7 | DS11: 34.92 | DT11: 6.45 | DU11: 21.85 | DV11: 12.4 | DW11: 13.61 | DX11: 11.75 | DY11: 11.19 | DZ11: 288.58 | EA11: 86.72 | EB11: 24.09 | EC11: 1315 | ED11: 22.32 | EE11: 26.07 | EF11: 16.85 | EG11: 49.27 | EH11: 459.77 | EI11: 213.68 | EJ11: 2.71 | EK11: 3939.4 | EL11: 28.24 | EM11: 290.71 | EN11: 119.19 | EO11: 141.51 | EP11: 1218.74 | EQ11: 60.85 | ER11: 105.14 | ES11: 51.41 | ET11: 41.69 | EU11: 12.31 | EV11: 282.51 | EW11: 6.19 | EX11: 141.32 | EY11: 115.69 | EZ11: 26.87 | FA11: 40.75 | FB11: 19.83 | FC11: 60 | FD11: 14.4 | FE11: 30.49 | FF11: 394.72 | FG11: 72.32 | FH11: 458.77 | FI11: 52.53 | FJ11: 27101.24 | FN11: =(B11-B10)/B10 -> 0.036092972 | FO11: =(C11-C10)/C10 -> -0.016803222 | FP11: =(D11-D10)/D10 -> 0.036051502 | FQ11: =(E11-E10)/E10 -> -0.048603027 | FR11: =(F11-F10)/F10 -> -0.010208417 | FS11: =(G11-G10)/G10 -> 0.10092961 | FT11: =(H11-H10)/H10 -> 0.028720023 | FU11: =(I11-I10)/I10 -> 0 | ... LV11: =(FJ11-FJ10)/FJ10 -> -0.018407814
A12: 44858 | B12: 2561.04 | C12: 72.71 | D12: 38.01 | E12: 32.18 | F12: 1855.86 | G12: 8.64 | H12: 190.65 | I12: 138738.94 | J12: 11.5 | K12: 230.14 | L12: 65.51 | M12: 0.06 | N12: 27.4 | O12: 1845.11 | P12: 1.49 | Q12: 881.75 | R12: 8.72 | S12: 153.32 | T12: 89.13 | U12: 53944.88 | V12: 15.08 | W12: 13.82 | X12: 4.38 | Y12: 523.74 | Z12: 60.53 | AA12: 228.52 | AB12: 2.82 | AC12: 10.08 | AD12: 13.35 | AE12: 103.41 | AF12: 613.71 | AG12: 55.51 | AH12: 20.4 | AI12: 129.54 | AJ12: 40.23 | AK12: 622.01 | AL12: 194.42 | AM12: 27.66 | AN12: 9.94 | AO12: 104.26 | AP12: 117.1 | AQ12: 10 | AR12: 8.95 | AS12: 98.19 | AT12: 56.33 | AU12: 102.96 | AV12: 20.67 | AW12: 46.01 | AX12: 4.02 | AY12: 25.13 | AZ12: 24.9 | BA12: 5927.35 | BB12: 466.75 | BC12: 2.42 | BD12: 13.5 | BE12: 325.68 | BF12: 295.72 | BG12: 102.87 | BH12: 49.83 | BI12: 209 | BJ12: 2.35 | BK12: 973.96 | BL12: 126.12 | BM12: 48.07 | BN12: 496.03 | BO12: 2896.2 | BP12: 97.75 | BQ12: 616.2 | BR12: 104.21 | BS12: 299.76 | BT12: 53.55 | BU12: 45.74 | BV12: 10.45 | BW12: 45.72 | BX12: 98.59 | BY12: 159.61 | BZ12: 34.19 | CA12: 165.63 | CB12: 37.63 | CC12: 55909.91 | CD12: 97.73 | CE12: 84.21 | CF12: 5517.56 | CG12: 56.1 | CH12: 0.65 | CI12: 101.21 | CJ12: 62.01 | CK12: 52.36 | CL12: 28.4 | CM12: 3.75 | CN12: 5.35 | CO12: 2.28 | CP12: 813.89 | CQ12: 131.17 | CR12: 155.76 | CS12: 94.07 | CT12: 204.61 | CU12: 402.65 | CV12: 74.54 | CW12: 323.73 | CX12: 13.57 | CY12: 186.12 | CZ12: 27.16 | DA12: 9443.31 | DB12: 117.1 | DC12: 4.78 | DD12: 21.49 | DE12: 1133.74 | DF12: 110.22 | DG12: 159.61 | DH12: 8.96 | DI12: 7.47 | DJ12: 20.95 | DK12: 89.27 | DL12: 11546.73 | DM12: 20.99 | DN12: 41.25 | DO12: 78.84 | DP12: 81.11 | DQ12: 721375.75 | DR12: 83.36 | DS12: 33.78 | DT12: 6.87 | DU12: 23.68 | DV12: 13.73 | DW12: 14.47 | DX12: 12.86 | DY12: 9.87 | DZ12: 298.83 | EA12: 93.99 | EB12: 25.06 | EC12: 1432.8 | ED12: 21.43 | EE12: 27.62 | EF12: 17.3 | EG12: 48.85 | EH12: 497.1 | EI12: 219.98 | EJ12: 2.61 | EK12: 3913.93 | EL12: 26.89 | EM12: 297.25 | EN12: 126.23 | EO12: 149.55 | EP12: 1221.62 | EQ12: 59.19 | ER12: 114.98 | ES12: 53.33 | ET12: 38.23 | EU12: 12.6 | EV12: 299.63 | EW12: 5.92 | EX12: 143.84 | EY12: 123.36 | EZ12: 28.41 | FA12: 39.52 | FB12: 21.84 | FC12: 59.4 | FD12: 14.44 | FE12: 33.72 | FF12: 386.59 | FG12: 76.42 | FH12: 490.13 | FI12: 55.85 | FJ12: 26625.38 | FN12: =(B12-B11)/B11 -> 0.040050032 | FO12: =(C12-C11)/C11 -> 0.026977401 | FP12: =(D12-D11)/D11 -> 0.049710025 | FQ12: =(E12-E11)/E11 -> -0.015601101 | FR12: =(F12-F11)/F11 -> 0.021386901 | FS12: =(G12-G11)/G11 -> 0.042219542 | FT12: =(H12-H11)/H11 -> 0.070947085 | FU12: =(I12-I11)/I11 -> -0.017963812 | ... LV12: =(FJ12-FJ11)/FJ11 -> -0.017558606
A13: 44865 | B13: 2507.22 | C13: 73.73 | D13: 37.77 | E13: 33.11 | F13: 1814.72 | G13: 7.93 | H13: 189.98 | I13: 137892.97 | J13: 12.28 | K13: 216.02 | L13: 65.71 | M13: 0.06 | N13: 27.5 | O13: 1847.75 | P13: 1.61 | Q13: 938.57 | R13: 9.7 | S13: 136.23 | T13: 92.49 | U13: 55921.91 | V13: 15.1 | W13: 14.14 | X13: 4.47 | Y13: 511.32 | Z13: 66.3 | AA13: 207.47 | AB13: 3.02 | AC13: 9.14 | AD13: 14.68 | AE13: 90.98 | AF13: 629.68 | AG13: 54.14 | AH13: 21.31 | AI13: 127.52 | AJ13: 40.05 | AK13: 613.61 | AL13: 194.96 | AM13: 26.83 | AN13: 10.05 | AO13: 108.05 | AP13: 121.37 | AQ13: 10.34 | AR13: 7.51 | AS13: 99.01 | AT13: 52.01 | AU13: 102.85 | AV13: 21.23 | AW13: 47.23 | AX13: 3.98 | AY13: 25.35 | AZ13: 22.39 | BA13: 6449.65 | BB13: 451.21 | BC13: 2.39 | BD13: 12.45 | BE13: 285.75 | BF13: 260.79 | BG13: 104.34 | BH13: 50.61 | BI13: 217.11 | BJ13: 2.36 | BK13: 1164.03 | BL13: 127.61 | BM13: 49.75 | BN13: 531.23 | BO13: 2945.78 | BP13: 98.82 | BQ13: 609.15 | BR13: 97.95 | BS13: 306.58 | BT13: 63.66 | BU13: 48.39 | BV13: 10.65 | BW13: 45.22 | BX13: 90.23 | BY13: 156.51 | BZ13: 32.15 | CA13: 162.5 | CB13: 40.29 | CC13: 55149.8 | CD13: 112.18 | CE13: 77.46 | CF13: 5546.91 | CG13: 35.72 | CH13: 0.67 | CI13: 99.22 | CJ13: 62.19 | CK13: 54.02 | CL13: 21.78 | CM13: 3.75 | CN13: 5.34 | CO13: 2.09 | CP13: 798.3 | CQ13: 132.69 | CR13: 163.92 | CS13: 92.44 | CT13: 192.53 | CU13: 417.83 | CV13: 73.23 | CW13: 312.82 | CX13: 13.83 | CY13: 221.16 | CZ13: 29.01 | DA13: 9046.35 | DB13: 121.37 | DC13: 4.5 | DD13: 21.76 | DE13: 1180.74 | DF13: 110.12 | DG13: 156.51 | DH13: 8.76 | DI13: 8.28 | DJ13: 21.19 | DK13: 91.14 | DL13: 11645.92 | DM13: 21.81 | DN13: 41.74 | DO13: 78.49 | DP13: 85.54 | DQ13: 727329.31 | DR13: 71.05 | DS13: 34.66 | DT13: 7.66 | DU13: 19.37 | DV13: 15 | DW13: 13.37 | DX13: 10.79 | DY13: 11.23 | DZ13: 311.03 | EA13: 92.69 | EB13: 25.69 | EC13: 1291.2 | ED13: 22.39 | EE13: 28.29 | EF13: 17.06 | EG13: 49 | EH13: 495.44 | EI13: 215.76 | EJ13: 2.53 | EK13: 4049.29 | EL13: 26.96 | EM13: 292.5 | EN13: 125.51 | EO13: 153.63 | EP13: 1340.61 | EQ13: 59.64 | ER13: 114.55 | ES13: 53.53 | ET13: 35.41 | EU13: 12.96 | EV13: 287.47 | EW13: 5.84 | EX13: 160.01 | EY13: 121.98 | EZ13: 29.07 | FA13: 39.44 | FB13: 23.19 | FC13: 60.4 | FD13: 14.74 | FE13: 32.92 | FF13: 396.53 | FG13: 77.91 | FH13: 467.5 | FI13: 58.96 | FJ13: 26738.68 | FN13: =(B13-B12)/B12 -> -0.0210149 | FO13: =(C13-C12)/C12 -> 0.014028332 | FP13: =(D13-D12)/D12 -> -0.0063141279 | FQ13: =(E13-E12)/E12 -> 0.028899938 | FR13: =(F13-F12)/F12 -> -0.02216762 | FS13: =(G13-G12)/G12 -> -0.082175926 | FT13: =(H13-H12)/H12 -> -0.0035142932 | FU13: =(I13-I12)/I12 -> -0.0060975671 | ... LV13: =(FJ13-FJ12)/FJ12 -> 0.0042553383
A14: 44872 | B14: 2674.08 | C14: 70.9 | D14: 43.84 | E14: 36.14 | F14: 1829.34 | G14: 8.41 | H14: 220.79 | I14: 145506.67 | J14: 10.47 | K14: 241.11 | L14: 69.36 | M14: 0.06 | N14: 26.85 | O14: 1987.11 | P14: 1.69 | Q14: 974.89 | R14: 10.3 | S14: 147.62 | T14: 99.17 | U14: 59216.98 | V14: 15.01 | W14: 16.31 | X14: 4.61 | Y14: 496.03 | Z14: 67.21 | AA14: 195.97 | AB14: 2.24 | AC14: 11.58 | AD14: 16.35 | AE14: 100.79 | AF14: 667.49 | AG14: 56.03 | AH14: 27.99 | AI14: 133.01 | AJ14: 40.72 | AK14: 658.65 | AL14: 212.24 | AM14: 29.34 | AN14: 10.19 | AO14: 107.1 | AP14: 125.66 | AQ14: 10.68 | AR14: 8.18 | AS14: 98.47 | AT14: 56.81 | AU14: 115.4 | AV14: 21.71 | AW14: 51.22 | AX14: 4.32 | AY14: 27.37 | AZ14: 24.2 | BA14: 6839.17 | BB14: 537.39 | BC14: 2.46 | BD14: 13.04 | BE14: 341.15 | BF14: 290.13 | BG14: 113.17 | BH14: 49.46 | BI14: 225.34 | BJ14: 2.29 | BK14: 1129.81 | BL14: 129.06 | BM14: 52.97 | BN14: 501.28 | BO14: 3036.01 | BP14: 110.55 | BQ14: 719.25 | BR14: 93.45 | BS14: 330.81 | BT14: 62.5 | BU14: 47.78 | BV14: 11.43 | BW14: 45.74 | BX14: 112.33 | BY14: 154.48 | BZ14: 39.44 | CA14: 161.83 | CB14: 41.19 | CC14: 57430.12 | CD14: 133.43 | CE14: 88.32 | CF14: 5703.44 | CG14: 39.78 | CH14: 0.67 | CI14: 103.13 | CJ14: 72.37 | CK14: 53.57 | CL14: 26.16 | CM14: 3.75 | CN14: 5.86 | CO14: 2.15 | CP14: 713.56 | CQ14: 135.95 | CR14: 177.76 | CS14: 106.07 | CT14: 200.37 | CU14: 416.01 | CV14: 74.91 | CW14: 333.38 | CX14: 13.57 | CY14: 239.51 | CZ14: 33.02 | DA14: 9582.87 | DB14: 125.66 | DC14: 4.26 | DD14: 23.36 | DE14: 1218.1 | DF14: 107.41 | DG14: 154.48 | DH14: 9.06 | DI14: 8.12 | DJ14: 20.48 | DK14: 100.94 | DL14: 11606.25 | DM14: 22.38 | DN14: 42.53 | DO14: 80.49 | DP14: 90.68 | DQ14: 741221 | DR14: 83.71 | DS14: 35.81 | DT14: 8.35 | DU14: 22.54 | DV14: 18.15 | DW14: 14.83 | DX14: 12.57 | DY14: 12.06 | DZ14: 277.81 | EA14: 98.73 | EB14: 26.12 | EC14: 1602 | ED14: 26.15 | EE14: 28.31 | EF14: 18.38 | EG14: 51.19 | EH14: 535.31 | EI14: 236.75 | EJ14: 2.64 | EK14: 3935.41 | EL14: 26.62 | EM14: 291.79 | EN14: 131.6 | EO14: 158.84 | EP14: 1396.19 | EQ14: 70.48 | ER14: 116.41 | ES14: 57.94 | ET14: 37.44 | EU14: 13.65 | EV14: 309.72 | EW14: 6.18 | EX14: 177.49 | EY14: 127.51 | EZ14: 29 | FA14: 40.38 | FB14: 24.58 | FC14: 62 | FD14: 15.9 | FE14: 32.03 | FF14: 367.62 | FG14: 73.08 | FH14: 495.43 | FI14: 63.29 | FJ14: 26605.96 | FN14: =(B14-B13)/B13 -> 0.066551798 | FO14: =(C14-C13)/C13 -> -0.03838329 | FP14: =(D14-D13)/D13 -> 0.16070956 | FQ14: =(E14-E13)/E13 -> 0.091513138 | FR14: =(F14-F13)/F13 -> 0.0080563393 | FS14: =(G14-G13)/G13 -> 0.060529634 | FT14: =(H14-H13)/H13 -> 0.16217497 | FU14: =(I14-I13)/I13 -> 0.055214562 | ... LV14: =(FJ14-FJ13)/FJ13 -> -0.0049635958
... A169: 45957 | B169: 4390.42 | C169: 222.5 | D169: 81.31 | E169: 43.45 | F169: 3138 | G169: 200.47 | H169: 238.4 | I169: 290000 | J169: 146.78 | K169: 517.81 | L169: 80.72 | M169: 0.07 | N169: 42.76 | O169: 5077.74 | P169: 5.58 | Q169: 2327.26 | R169: 43.2 | S169: 270.11 | T169: 90.22 | U169: 107500 | V169: 18.5 | W169: 202.49 | X169: 20.13 | Y169: 341.56 | Z169: 170.43 | AA169: 456.56 | AB169: 3.38 | AC169: 7.8 | AD169: 27.89 | AE169: 244.22 | AF169: 612.1 | AG169: 68.9 | AH169: 7.02 | AI169: 204.19 | AJ169: 24.22 | AK169: 115.8 | AL169: 403.95 | AM169: 39.99 | AN169: 21.44 | AO169: 213.4 | AP169: 311.12 | AQ169: 20.3 | AR169: 11.17 | AS169: 76.88 | AT169: 99.85 | AU169: 160.07 | AV169: 30.5 | AW169: 56.21 | AX169: 6.91 | AY169: 27.67 | AZ169: 33.1 | BA169: 27065 | BB169: 916.48 | BC169: 5.45 | BD169: 23.53 | BE169: 340.31 | BF169: 1118.86 | BG169: 245.55 | BH169: 74.92 | BI169: 577.26 | BJ169: 8.71 | BK169: 1798.5 | BL169: 200.06 | BM169: 308.95 | BN169: 364.45 | BO169: 3058 | BP169: 142.67 | BQ169: 1082.81 | BR169: 112.62 | BS169: 362.65 | BT169: 100.6 | BU169: 53.95 | BV169: 12.98 | BW169: 101.18 | BX169: 648.35 | BY169: 188.87 | BZ169: 173.86 | CA169: 146.09 | CB169: 67.06 | CC169: 119900 | CD169: 163.8 | CE169: 87.23 | CF169: 7570 | CG169: 14 | CH169: 1.79 | CI169: 158.5 | CJ169: 256.12 | CK169: 49.46 | CL169: 25.52 | CM169: 7.78 | CN169: 11.36 | CO169: 16.71 | CP169: 1871 | CQ169: 218.04 | CR169: 398.85 | CS169: 260.01 | CT169: 340.07 | CU169: 410 | CV169: 262.61 | CW169: 551.99 | CX169: 13.05 | CY169: 629 | CZ169: 56.15 | DA169: 13355 | DB169: 311.12 | DC169: 9.54 | DD169: 32.4 | DE169: 2308 | DF169: 307.9 | DG169: 188.87 | DH169: 17.57 | DI169: 10.6 | DJ169: 35.87 | DK169: 64.59 | DL169: 12410 | DM169: 37.63 | DN169: 59.67 | DO169: 67.04 | DP169: 80.87 | DQ169: 322000 | DR169: 655.32 | DS169: 51.5 | DT169: 51.96 | DU169: 47.52 | DV169: 8.15 | DW169: 1.7 | DX169: 15.86 | DY169: 12.09 | DZ169: 241.63 | EA169: 166.5 | EB169: 30.54 | EC169: 1488.6 | ED169: 38.09 | EE169: 27.21 | EF169: 16.57 | EG169: 34.46 | EH169: 1308.51 | EI169: 215.38 | EJ169: 8.02 | EK169: 4588.61 | EL169: 25.64 | EM169: 258.9 | EN169: 150.37 | EO169: 262 | EP169: 5318 | EQ169: 300.43 | ER169: 167.92 | ES169: 263.61 | ET169: 76.4 | EU169: 26.66 | EV169: 477.54 | EW169: 19.05 | EX169: 201.02 | EY169: 305.72 | EZ169: 35.13 | FA169: 85.25 | FB169: 36.91 | FC169: 73 | FD169: 10.1 | FE169: 24.73 | FF169: 596 | FG169: 87.6 | FH169: 910.16 | FI169: 68.54 | FJ169: 56660 | FN169: =(B169-B168)/B168 -> 0.0043808779 | FO169: =(C169-C168)/C168 -> -0.085115132 | FP169: =(D169-D168)/D168 -> -0.16347737 | FQ169: =(E169-E168)/E168 -> 0.0048566142 | FR169: =(F169-F168)/F168 -> 0.0035177486 | FS169: =(G169-G168)/G168 -> 0.085793208 | FT169: =(H169-H168)/H168 -> -0.029315961 | FU169: =(I169-I168)/I168 -> 0.14851485 | ... LV169: =(FJ169-FJ168)/FJ168 -> 0.023852548
A170: 45964 | B170: 4325.03 | C170: 226.7 | D170: 83.8 | E170: 42.65 | F170: 3118 | G170: 177.93 | H170: 237.6 | I170: 264000 | J170: 130.36 | K170: 496.82 | L170: 84.3 | M170: 0.07 | N170: 42.59 | O170: 4940 | P170: 5.57 | Q170: 2108.6 | R170: 42.24 | S170: 268.21 | T170: 92.82 | U170: 97900 | V170: 18.5 | W170: 188.15 | X170: 20.42 | Y170: 324.21 | Z170: 166.34 | AA170: 429.52 | AB170: 3.54 | AC170: 8.21 | AD170: 27.71 | AE170: 244.41 | AF170: 603.2 | AG170: 70.55 | AH170: 5.96 | AI170: 201.98 | AJ170: 24.01 | AK170: 117.55 | AL170: 413.26 | AM170: 38.13 | AN170: 22.4 | AO170: 208.05 | AP170: 314.21 | AQ170: 21.17 | AR170: 11.33 | AS170: 79.12 | AT170: 102 | AU170: 158.64 | AV170: 29.81 | AW170: 58.19 | AX170: 6.84 | AY170: 26.28 | AZ170: 27.09 | BA170: 21700 | BB170: 870.8 | BC170: 4.93 | BD170: 24.55 | BE170: 326.95 | BF170: 1103.66 | BG170: 241.6 | BH170: 75.59 | BI170: 563.1 | BJ170: 8.85 | BK170: 1720.5 | BL170: 200.6 | BM170: 307.27 | BN170: 357.6 | BO170: 2991.8 | BP170: 132.93 | BQ170: 1082.2 | BR170: 110.74 | BS170: 354.45 | BT170: 97.9 | BU170: 53.58 | BV170: 13.06 | BW170: 102.59 | BX170: 621.71 | BY170: 186.57 | BZ170: 152.41 | CA170: 142.95 | CB170: 65.49 | CC170: 110100 | CD170: 159.35 | CE170: 81.69 | CF170: 7550 | CG170: 16.26 | CH170: 1.76 | CI170: 147.6 | CJ170: 233.54 | CK170: 45.68 | CL170: 23.6 | CM170: 7.76 | CN170: 11.12 | CO170: 12.86 | CP170: 1807 | CQ170: 219.16 | CR170: 401.47 | CS170: 251.96 | CT170: 335.36 | CU170: 405.7 | CV170: 239.26 | CW170: 551.97 | CX170: 13.03 | CY170: 634 | CZ170: 57.95 | DA170: 12905 | DB170: 314.21 | DC170: 12.02 | DD170: 32.1 | DE170: 2208.5 | DF170: 301.1 | DG170: 186.57 | DH170: 17.64 | DI170: 10.77 | DJ170: 36.01 | DK170: 61.09 | DL170: 12450 | DM170: 37.51 | DN170: 60.94 | DO170: 69.8 | DP170: 85.57 | DQ170: 306000 | DR170: 616.91 | DS170: 52.55 | DT170: 39.76 | DU170: 38.6 | DV170: 6.55 | DW170: 1.59 | DX170: 14.3 | DY170: 12.15 | DZ170: 245.53 | EA170: 164.84 | EB170: 31.12 | EC170: 1337.2 | ED170: 39.16 | EE170: 26.16 | EF170: 16.5 | EG170: 34.88 | EH170: 1284.76 | EI170: 209.94 | EJ170: 8.51 | EK170: 4617.61 | EL170: 25.7 | EM170: 268.4 | EN170: 146.98 | EO170: 261.1 | EP170: 5138 | EQ170: 286.5 | ER170: 169.32 | ES170: 252.62 | ET170: 76.2 | EU170: 26.64 | EV170: 499.06 | EW170: 19.58 | EX170: 194.61 | EY170: 304.7 | EZ170: 36.58 | FA170: 87.15 | FB170: 37.06 | FC170: 70.1 | FD170: 8.25 | FE170: 24.28 | FF170: 596 | FG170: 85.44 | FH170: 922.74 | FI170: 69.86 | FJ170: 57210 | FK170: =SUM(D171:FJ171) -> 1001029.8 | FN170: =(B170-B169)/B169 -> -0.014893791 | FO170: =(C170-C169)/C169 -> 0.018876404 | FP170: =(D170-D169)/D169 -> 0.03062354 | FQ170: =(E170-E169)/E169 -> -0.018411968 | FR170: =(F170-F169)/F169 -> -0.0063734863 | FS170: =(G170-G169)/G169 -> -0.11243578 | FT170: =(H170-H169)/H169 -> -0.0033557047 | FU170: =(I170-I169)/I169 -> -0.089655172 | ... LV170: =(FJ170-FJ169)/FJ169 -> 0.0097070244
A171: 45971 | B171: 4343.64 | C171: 222.8 | D171: 84.43 | E171: 42.75 | F171: 3198 | G171: 172.14 | H171: 242.4 | I171: 278500 | J171: 121.53 | K171: 503.29 | L171: 89.06 | M171: 0.07 | N171: 40.67 | O171: 5075.61 | P171: 5.98 | Q171: 2031.05 | R171: 43.5 | S171: 272.95 | T171: 98.98 | U171: 102800 | V171: 18.6 | W171: 186.86 | X171: 21.61 | Y171: 332.52 | Z171: 159.84 | AA171: 401.99 | AB171: 3.66 | AC171: 8.58 | AD171: 29.44 | AE171: 237.58 | AF171: 636.8 | AG171: 71.07 | AH171: 5.88 | AI171: 203.26 | AJ171: 25.79 | AK171: 126.95 | AL171: 417.81 | AM171: 35.91 | AN171: 21.65 | AO171: 210.25 | AP171: 309.48 | AQ171: 21.93 | AR171: 11.5 | AS171: 81.09 | AT171: 100.73 | AU171: 159.81 | AV171: 29.73 | AW171: 59.44 | AX171: 6.78 | AY171: 24.98 | AZ171: 26.77 | BA171: 21170 | BB171: 881.5 | BC171: 3.89 | BD171: 23.81 | BE171: 333.6 | BF171: 1154.23 | BG171: 227 | BH171: 75.92 | BI171: 553.55 | BJ171: 9.55 | BK171: 1765 | BL171: 201.34 | BM171: 304.17 | BN171: 373.1 | BO171: 3105.7 | BP171: 131.65 | BQ171: 1069.65 | BR171: 107.61 | BS171: 359.1 | BT171: 102.8 | BU171: 56.19 | BV171: 13.28 | BW171: 102.54 | BX171: 609.89 | BY171: 195.25 | BZ171: 146.34 | CA171: 145.02 | CB171: 69.59 | CC171: 118000 | CD171: 164.8 | CE171: 84.04 | CF171: 7550 | CG171: 17.53 | CH171: 1.75 | CI171: 154.5 | CJ171: 247.96 | CK171: 49.16 | CL171: 23.44 | CM171: 7.98 | CN171: 10.86 | CO171: 10.03 | CP171: 1806.5 | CQ171: 232.29 | CR171: 430 | CS171: 251.86 | CT171: 336.08 | CU171: 397.95 | CV171: 217.57 | CW171: 555.57 | CX171: 13.52 | CY171: 656 | CZ171: 60.95 | DA171: 12580 | DB171: 309.48 | DC171: 12.74 | DD171: 32.54 | DE171: 2314 | DF171: 306.9 | DG171: 195.25 | DH171: 17.98 | DI171: 11.2 | DJ171: 35.22 | DK171: 66.03 | DL171: 12670 | DM171: 38.95 | DN171: 60.33 | DO171: 70.86 | DP171: 86.44 | DQ171: 334500 | DR171: 645.33 | DS171: 55.05 | DT171: 35.09 | DU171: 37.29 | DV171: 6.22 | DW171: 1.46 | DX171: 14.09 | DY171: 12.38 | DZ171: 241.63 | EA171: 170.62 | EB171: 29 | EC171: 1458.2 | ED171: 39.9 | EE171: 24.96 | EF171: 16.96 | EG171: 37.28 | EH171: 1325.04 | EI171: 221.2 | EJ171: 8.96 | EK171: 4564 | EL171: 25.86 | EM171: 289.9 | EN171: 147.96 | EO171: 267.7 | EP171: 5349 | EQ171: 282.2 | ER171: 172.3 | ES171: 248.83 | ET171: 79.6 | EU171: 27.84 | EV171: 513.11 | EW171: 20.09 | EX171: 194.58 | EY171: 304.86 | EZ171: 36.49 | FA171: 87.85 | FB171: 38.08 | FC171: 69.9 | FD171: 7.92 | FE171: 24.96 | FF171: 596 | FG171: 90.44 | FH171: 925.08 | FI171: 74.38 | FJ171: 57020 | FK171: =SUM(D172:FJ172) -> 915693.67 | FN171: =(B171-B170)/B170 -> 0.0043028603 | FO171: =(C171-C170)/C170 -> -0.017203352 | FP171: =(D171-D170)/D170 -> 0.0075178998 | FQ171: =(E171-E170)/E170 -> 0.0023446659 | FR171: =(F171-F170)/F170 -> 0.025657473 | FS171: =(G171-G170)/G170 -> -0.032540887 | FT171: =(H171-H170)/H170 -> 0.02020202 | FU171: =(I171-I170)/I170 -> 0.054924242 | ... LV171: =(FJ171-FJ170)/FJ170 -> -0.0033210977
A172: 45978 | B172: 4285.88 | C172: 233 | D172: 80.84 | E172: 40.37 | F172: 3097 | G172: 154.85 | H172: 239.4 | I172: 259500 | J172: 107.3 | K172: 471.24 | L172: 85.08 | M172: 0.07 | N172: 40.56 | O172: 4768 | P172: 5.43 | Q172: 1951.78 | R172: 38.08 | S172: 271.49 | T172: 94.72 | U172: 94800 | V172: 18.36 | W172: 178.88 | X172: 20.4 | Y172: 319.97 | Z172: 152.93 | AA172: 391.09 | AB172: 3.48 | AC172: 7.69 | AD172: 28.53 | AE172: 220.69 | AF172: 623 | AG172: 72.95 | AH172: 5.33 | AI172: 197.62 | AJ172: 25.04 | AK172: 126.5 | AL172: 389.19 | AM172: 34.5 | AN172: 21.17 | AO172: 202.75 | AP172: 298.02 | AQ172: 21.62 | AR172: 12 | AS172: 80.77 | AT172: 93.52 | AU172: 160.63 | AV172: 29.58 | AW172: 57.02 | AX172: 5.94 | AY172: 23.96 | AZ172: 24.96 | BA172: 17090 | BB172: 834 | BC172: 3.4 | BD172: 21.34 | BE172: 324.19 | BF172: =104.31*10 -> 1043.1 | BG172: 219.15 | BH172: 73.27 | BI172: 550.43 | BJ172: 8.81 | BK172: 1737.5 | BL172: 200.69 | BM172: 287.44 | BN172: 335 | BO172: 3150.6 | BP172: 127.15 | BQ172: 1014.72 | BR172: 104.28 | BS172: 361.5 | BT172: 92.75 | BU172: 55.97 | BV172: 12.83 | BW172: 105.32 | BX172: 594.25 | BY172: 203.9 | BZ172: 147.8 | CA172: 146.33 | CB172: 70.47 | CC172: 114000 | CD172: 151.6 | CE172: 78.63 | CF172: 7710 | CG172: 21.28 | CH172: 1.63 | CI172: 147 | CJ172: 203.78 | CK172: 47.63 | CL172: 24 | CM172: 8.11 | CN172: 9.68 | CO172: 10.2 | CP172: 1713 | CQ172: 236.28 | CR172: 414.92 | CS172: 236.7 | CT172: 327.98 | CU172: 362.25 | CV172: 198.76 | CW172: 540.4 | CX172: 12.98 | CY172: 610 | CZ172: 56.9 | DA172: 12600 | DB172: 298.02 | DC172: 11.78 | DD172: 33.06 | DE172: 2358 | DF172: 289.4 | DG172: 203.9 | DH172: 17.93 | DI172: 10.88 | DJ172: 34.9 | DK172: 62.8 | DL172: 12650 | DM172: 38.14 | DN172: 60.4 | DO172: 70.68 | DP172: 85.35 | DQ172: 288500 | DR172: 583.61 | DS172: 53.45 | DT172: 32.19 | DU172: 37.09 | DV172: 5.54 | DW172: 1.3 | DX172: 13.01 | DY172: 12.09 | DZ172: 234.9 | EA172: 168.09 | EB172: 28.48 | EC172: 1301 | ED172: 39.79 | EE172: 19 | EF172: 17.7 | EG172: 35.78 | EH172: 1347.22 | EI172: 227.39 | EJ172: 8.7 | EK172: 4585 | EL172: 25.27 | EM172: 315.6 | EN172: 150.92 | EO172: 269.4 | EP172: 4710 | EQ172: 275.06 | ER172: 165.94 | ES172: 251.32 | ET172: 78.25 | EU172: 27.76 | EV172: 504.04 | EW172: 18.61 | EX172: 179.7 | EY172: 297.44 | EZ172: 35.98 | FA172: 86 | FB172: 37.3 | FC172: 69.3 | FD172: 6.85 | FE172: 25.29 | FF172: 597 | FG172: 86.32 | FH172: 899.01 | FI172: 70.54 | FJ172: 54800 | FK172: =SUM(D173:FJ173) -> 936307.53 | FN172: =(B172-B171)/B171 -> -0.013297603 | FO172: =(C172-C171)/C171 -> 0.045780969 | FP172: =(D172-D171)/D171 -> -0.042520431 | FQ172: =(E172-E171)/E171 -> -0.055672515 | FR172: =(F172-F171)/F171 -> -0.031582239 | FS172: =(G172-G171)/G171 -> -0.1004415 | FT172: =(H172-H171)/H171 -> -0.012376238 | FU172: =(I172-I171)/I171 -> -0.068222621 | ... LV172: =(FJ172-FJ171)/FJ171 -> -0.038933707
A173: 45985 | B173: 4398.44 | C173: 240.5 | D173: 82.5 | E173: 41.67 | F173: 3133 | G173: 168.45 | H173: 243.2 | I173: 259000 | J173: 128.49 | K173: 492.01 | L173: 88.04 | M173: 0.07 | N173: 40.1 | O173: 4914.69 | P173: 5.4 | Q173: 2071.78 | R173: 41.02 | S173: 278.85 | T173: 98.38 | U173: 100500 | V173: 17.52 | W173: 177 | X173: 21.55 | Y173: 329.77 | Z173: 157.3 | AA173: 430.17 | AB173: 3.7 | AC173: 7.68 | AD173: 29.35 | AE173: 233.22 | AF173: 635.5 | AG173: 73.12 | AH173: 6.19 | AI173: 201.87 | AJ173: 25.74 | AK173: 136.75 | AL173: 391.9 | AM173: 40.56 | AN173: 21.16 | AO173: 204.45 | AP173: 313.08 | AQ173: 21.9 | AR173: 12.65 | AS173: 79.83 | AT173: 95.98 | AU173: 161.72 | AV173: 30.25 | AW173: 58.16 | AX173: 6.08 | AY173: 24.42 | AZ173: 26.12 | BA173: 16825 | BB173: 903.4 | BC173: 3.52 | BD173: 23.21 | BE173: 320.13 | BF173: =107.58*10 -> 1075.8 | BG173: 228.3 | BH173: 73.77 | BI173: 575.76 | BJ173: 9.24 | BK173: 1961.5 | BL173: 202.03 | BM173: 298.45 | BN173: 360.8 | BO173: 3137.5 | BP173: 129.03 | BQ173: 1047.3 | BR173: 104.47 | BS173: 375.6 | BT173: 97.5 | BU173: 56.8 | BV173: 13.28 | BW173: 110.51 | BX173: 647.95 | BY173: 205.61 | BZ173: 158.64 | CA173: 148.74 | CB173: 73.69 | CC173: 114100 | CD173: 160.4 | CE173: 84.96 | CF173: 7740 | CG173: 21.01 | CH173: 1.65 | CI173: 150 | CJ173: 217.53 | CK173: 49.35 | CL173: 28.12 | CM173: 8.43 | CN173: 9.68 | CO173: 11.7 | CP173: 1650.5 | CQ173: 227.7 | CR173: 428.5 | CS173: 241.75 | CT173: 334.44 | CU173: 356.8 | CV173: 201.95 | CW173: 550.53 | CX173: 13.27 | CY173: 611.5 | CZ173: 56.7 | DA173: 12875 | DB173: 313.08 | DC173: 11.99 | DD173: 33.14 | DE173: 2441 | DF173: 290.3 | DG173: 205.61 | DH173: 18.18 | DI173: 11.15 | DJ173: 34.64 | DK173: 64.63 | DL173: 13060 | DM173: 38.9 | DN173: 60.59 | DO173: 70.18 | DP173: 87.11 | DQ173: 299500 | DR173: 598.87 | DS173: 54.95 | DT173: 33.85 | DU173: 44.96 | DV173: 6.52 | DW173: 1.31 | DX173: 13.86 | DY173: 12.61 | DZ173: 233.1 | EA173: 172.05 | EB173: 28.7 | EC173: 1340.6 | ED173: 43.12 | EE173: 21.59 | EF173: 17.48 | EG173: 37.13 | EH173: 1360.17 | EI173: 226.78 | EJ173: 8.68 | EK173: 4544 | EL173: 24.54 | EM173: 307.4 | EN173: 148.16 | EO173: 282.8 | EP173: 4968 | EQ173: 291.51 | ER173: 165.12 | ES173: 266.54 | ET173: 79.86 | EU173: 27.5 | EV173: 513.81 | EW173: 18.72 | EX173: 189 | EY173: 308.58 | EZ173: 36.1 | FA173: 87.3 | FB173: 37.42 | FC173: 73.3 | FD173: 6.86 | FE173: 25.11 | FF173: 596 | FG173: 85.76 | FH173: 913.59 | FI173: 72.38 | FJ173: 57140 | FK173: 1018352.1 | FN173: =(B173-B172)/B172 -> 0.026262984 | FO173: =(C173-C172)/C172 -> 0.032188841 | FP173: =(D173-D172)/D172 -> 0.020534389 | FQ173: =(E173-E172)/E172 -> 0.03220213 | FR173: =(F173-F172)/F172 -> 0.011624152 | FS173: =(G173-G172)/G172 -> 0.087826929 | FT173: =(H173-H172)/H172 -> 0.015873016 | FU173: =(I173-I172)/I172 -> -0.0019267823 | ... LV173: =(FJ173-FJ172)/FJ172 -> 0.04270073
A174: 45992 | B174: 4418.63 | C174: 247.5 | D174: 82.47 | E174: 44.84 | F174: 3032 | G174: 181.76 | H174: 242.6 | I174: 315000 | J174: 131.95 | K174: 483.16 | L174: 96.46 | M174: 0.07 | N174: 40.86 | O174: 5187.12 | P174: 5.61 | Q174: 2066.42 | R174: 42.78 | S174: 278.78 | T174: 106.9 | U174: 108400 | V174: 17.24 | W174: 182.4 | X174: 21.8 | Y174: 330.91 | Z174: 158.32 | AA174: 455 | AB174: 3.31 | AC174: 7.91 | AD174: 28.03 | AE174: 229.53 | AF174: 622.72 | AG174: 69.51 | AH174: 6.07 | AI174: 196.56 | AJ174: 26.03 | AK174: 137.85 | AL174: 393.21 | AM174: 41.41 | AN174: 19.94 | AO174: 196.7 | AP174: 315.04 | AQ174: 21.41 | AR174: 12.74 | AS174: 78.82 | AT174: 92.2 | AU174: 164.93 | AV174: 29.43 | AW174: 61.6 | AX174: 6.07 | AY174: 25.91 | AZ174: 26.75 | BA174: 19285 | BB174: 951.6 | BC174: 3.75 | BD174: 23.68 | BE174: 346.26 | BF174: 100.24 | BG174: 233.45 | BH174: 73.01 | BI174: 603.17 | BJ174: 9.46 | BK174: 1851 | BL174: 203.73 | BM174: 283.94 | BN174: 379.85 | BO174: 3238.2 | BP174: 129.47 | BQ174: 1066.97 | BR174: 105.3 | BS174: 372.75 | BT174: 99.15 | BU174: 56.4 | BV174: 13.03 | BW174: 115.11 | BX174: 673.42 | BY174: 201.93 | BZ174: 161.08 | CA174: 143.62 | CB174: 75.39 | CC174: 123600 | CD174: 164.3 | CE174: 87.65 | CF174: 7700 | CG174: 20.92 | CH174: 1.77 | CI174: 148.2 | CJ174: 217.97 | CK174: 47.86 | CL174: 27.84 | CM174: 8.08 | CN174: 10.03 | CO174: 12.84 | CP174: 1673 | CQ174: 226.08 | CR174: 419.75 | CS174: 247.26 | CT174: 331.24 | CU174: 353.6 | CV174: 217.58 | CW174: 545.52 | CX174: 13.5 | CY174: 610 | CZ174: 60.45 | DA174: 13260 | DB174: 315.04 | DC174: 11.53 | DD174: 33.4 | DE174: 2293 | DF174: 292.9 | DG174: 201.93 | DH174: 17.97 | DI174: 10.72 | DJ174: 35.33 | DK174: 65.44 | DL174: 12260 | DM174: 38.55 | DN174: 59.48 | DO174: 69.36 | DP174: 85.12 | DQ174: 307500 | DR174: 564.93 | DS174: 56.1 | DT174: 34.69 | DU174: 46.75 | DV174: 6.53 | DW174: 1.2 | DX174: 18.67 | DY174: 12.9 | DZ174: 235.6 | EA174: 167.48 | EB174: 28.37 | EC174: 1349.4 | ED174: 42.26 | EE174: 23 | EF174: 18.07 | EG174: 40.47 | EH174: 1346.86 | EI174: 226.25 | EJ174: 8.83 | EK174: 4456 | EL174: 24.42 | EM174: 310.9 | EN174: 143.45 | EO174: 296.6 | EP174: 4883 | EQ174: 294.72 | ER174: 163.06 | ES174: 249 | ET174: 82.23 | EU174: 27.22 | EV174: 504.34 | EW174: 18.46 | EX174: 201.89 | EY174: 307.94 | EZ174: 35.83 | FA174: 87.15 | FB174: 37.21 | FC174: 81.2 | FD174: 6.87 | FE174: 24.34 | FF174: 596 | FG174: 85 | FH174: 894.68 | FI174: 73.96 | FJ174: 56740 | FK174: =SUM(D175:FJ175) -> 1009036.1 | FN174: =(B174-B173)/B173 -> 0.0045902638 | FO174: =(C174-C173)/C173 -> 0.029106029 | FP174: =(D174-D173)/D173 -> -0.00036363636 | FQ174: =(E174-E173)/E173 -> 0.076073914 | FR174: =(F174-F173)/F173 -> -0.032237472 | FS174: =(G174-G173)/G173 -> 0.079014544 | FT174: =(H174-H173)/H173 -> -0.0024671053 | FU174: =(I174-I173)/I173 -> 0.21621622 | ... LV174: =(FJ174-FJ173)/FJ173 -> -0.00700035
A175: 45999 | B175: 4407.82 | C175: 235.3 | D175: 84.4 | E175: 45.59 | F175: 3260 | G175: 187.54 | H175: 238.2 | I175: 301500 | J175: 123.38 | K175: 483.47 | L175: 96.14 | M175: 0.07 | N175: 42.13 | O175: 5279.68 | P175: 5.67 | Q175: 2019.81 | R175: 42.96 | S175: 278.03 | T175: 108.6 | U175: 108900 | V175: 17.51 | W175: 180.93 | X175: 22.76 | Y175: 334.48 | Z175: 156.9 | AA175: 446.89 | AB175: 3.41 | AC175: 7.64 | AD175: 26.73 | AE175: 230.28 | AF175: 624.5 | AG175: 69.11 | AH175: 5.62 | AI175: 203.56 | AJ175: 25.8 | AK175: 138.3 | AL175: 367.96 | AM175: 39.51 | AN175: 18.6 | AO175: 194.02 | AP175: 317.38 | AQ175: 21.7 | AR175: 12.51 | AS175: 77.95 | AT175: 93.59 | AU175: 170.31 | AV175: 30.82 | AW175: 61.69 | AX175: 6.36 | AY175: 25.11 | AZ175: 26.88 | BA175: 17895 | BB175: 925.3 | BC175: 3.34 | BD175: 23.87 | BE175: 350.43 | BF175: 94.09 | BG175: 238.85 | BH175: 72.33 | BI175: 625.61 | BJ175: 9.63 | BK175: 2175 | BL175: 203.66 | BM175: 288.42 | BN175: 375.5 | BO175: 3220.5 | BP175: 132.75 | BQ175: 1101.84 | BR175: 111.46 | BS175: 370.05 | BT175: 98.5 | BU175: 55.59 | BV175: 13.63 | BW175: 115.52 | BX175: 652.71 | BY175: 210.01 | BZ175: 164.75 | CA175: 149.04 | CB175: 78.09 | CC175: 125800 | CD175: 167.5 | CE175: 90.24 | CF175: 7450 | CG175: 20.97 | CH175: 1.73 | CI175: 146.1 | CJ175: 221.43 | CK175: 50.29 | CL175: 27.44 | CM175: 7.97 | CN175: 9.62 | CO175: 12.83 | CP175: 1700.5 | CQ175: 223.98 | CR175: 454.85 | CS175: 247.39 | CT175: 345.63 | CU175: 347.45 | CV175: 198.85 | CW175: 563.37 | CX175: 14.17 | CY175: 616 | CZ175: 63.75 | DA175: 14645 | DB175: 317.38 | DC175: 12.35 | DD175: 32.7 | DE175: 2306 | DF175: 291.3 | DG175: 210.01 | DH175: 17.88 | DI175: 11.14 | DJ175: 35.81 | DK175: 67.74 | DL175: 11930 | DM175: 40.38 | DN175: 64.82 | DO175: 69.64 | DP175: 84.74 | DQ175: 308000 | DR175: 598.87 | DS175: 55.4 | DT175: 34.02 | DU175: 49.13 | DV175: 6.51 | DW175: 0.89 | DX175: 18.03 | DY175: 13.29 | DZ175: 232.7 | EA175: 168.6 | EB175: 28.05 | EC175: 1333.8 | ED175: 45.51 | EE175: 23.48 | EF175: 17.8 | EG175: 40.86 | EH175: 1317.49 | EI175: 232.37 | EJ175: 8.24 | EK175: 4835.5 | EL175: 23.89 | EM175: 316.8 | EN175: 140.76 | EO175: 296.4 | EP175: 5010 | EQ175: 304.03 | ER175: 158.6 | ES175: 234.43 | ET175: 79.32 | EU175: 26.96 | EV175: 495.85 | EW175: 18.42 | EX175: 200.71 | EY175: 310.74 | EZ175: 35.53 | FA175: 86.5 | FB175: 37.39 | FC175: 80 | FD175: 6.32 | FE175: 24.39 | FF175: 596 | FG175: 83.32 | FH175: 884.48 | FI175: 75.8 | FJ175: 57120 | FK175: =SUM(C167:FJ167) -> 872572.54 | FN175: =(B175-B174)/B174 -> -0.0024464596 | FO175: =(C175-C174)/C174 -> -0.049292929 | FP175: =(D175-D174)/D174 -> 0.023402449 | FQ175: =(E175-E174)/E174 -> 0.016726137 | FR175: =(F175-F174)/F174 -> 0.075197889 | FS175: =(G175-G174)/G174 -> 0.031800176 | FT175: =(H175-H174)/H174 -> -0.018136851 | FU175: =(I175-I174)/I174 -> -0.042857143 | ... LV175: =(FJ175-FJ174)/FJ174 -> 0.0066972154
A177: Weights t = 0 | C177: =C167/$FK$175 -> 0.00028490468 | D177: =D167/$FK$175 -> 0.00010544682 | E177: =E167/$FK$175 -> 4.9967192e-05 | F177: =F167/$FK$175 -> 0.0033618981 | G177: =G167/$FK$175 -> 0.00020416641 | H177: =H167/$FK$175 -> 0.00027436114 | I177: =I167/$FK$175 -> 0.27848688 | J177: =J167/$FK$175 -> 0.0001488816 | ... FJ177: =FJ167/$FK$175 -> 0.059112564 | FK177: =SUM(D171:FJ171) -> 1001029.8
A178: Weights t = 1 | C178: =C171/$FK$177 -> 0.00022257079 | D178: =D171/$FK$177 -> 8.4343142e-05 | E178: =E171/$FK$177 -> 4.270602e-05 | F178: =F171/$FK$177 -> 0.00319471 | G178: =G171/$FK$177 -> 0.00017196291 | H178: =H171/$FK$177 -> 0.00024215063 | I178: =I171/$FK$177 -> 0.27821349 | J178: =J171/$FK$177 -> 0.00012140497 | ... FJ178: =FJ171/$FK$177 -> 0.05696134 | FK178: =SUM(D172:FJ172) -> 915693.67
A179: Weights t = 2 | C179: =C172/$FK$178 -> 0.00025445191 | D179: =D172/$FK$178 -> 8.8282799e-05 | E179: =E172/$FK$178 -> 4.4086796e-05 | F179: =F172/$FK$178 -> 0.0033821354 | G179: =G172/$FK$178 -> 0.00016910677 | H179: =H172/$FK$178 -> 0.00026144114 | I179: =I172/$FK$178 -> 0.28339172 | J179: =J172/$FK$178 -> 0.00011717893 | ... FJ179: =FJ172/$FK$178 -> 0.059845341 | FK179: =SUM(D173:FJ173) -> 936307.53
A180: Weights t = 3 | C180: =C173/$FK$179 -> 0.00025686005 | D180: =D173/$FK$179 -> 8.8112076e-05 | E180: =E173/$FK$179 -> 4.4504608e-05 | F180: =F173/$FK$179 -> 0.0033461228 | G180: =G173/$FK$179 -> 0.00017990884 | H180: =H173/$FK$179 -> 0.00025974372 | I180: =I173/$FK$179 -> 0.27661852 | J180: =J173/$FK$179 -> 0.00013723055 | ... FJ180: =FJ173/$FK$179 -> 0.061026958 | FK180: =SUM(D174:FJ174) -> 1018352.1
A181: Weights t = 4 | C181: =C174/$FK180 -> 0.0002430397 | D181: =D174/$FK$180 -> 8.0983775e-05 | E181: =E174/$FK$180 -> 4.403192e-05 | F181: =F174/$FK$180 -> 0.0029773591 | G181: =G174/$FK$180 -> 0.00017848443 | H181: =H174/$FK$180 -> 0.00023822801 | I181: =I174/$FK$180 -> 0.30932326 | J181: =J174/$FK$180 -> 0.00012957208 | K181: =K174/$FK$180 -> 0.00047445278 | ... FJ181: =FJ174/$FK$180 -> 0.055717466 | FK181: =SUM(D175:FJ175) -> 1009036.1
